Workbook

Sheet 1.1 HR-Ho so nhan su
A1: HỒ SƠ NHÂN SỰ
A3: STT | B3: Mã nhân viên | C3: Phòng | D3: Tên nhân viên (khôngdấu) | E3: Tên nhân viên | F3: VP | G3: Chức vụ | H3: Cấp bậc | K3: Hợp đồng LD - Trạng thái | L3: Ngày (Hợp đồng) | P3: Ngày sinh | Q3: Giới tính | R3: Số điện thoại | S3: Hộ khẩu | T3: Nơi tạm trú/Chỗ ở hiện tại | U3: CMND | V3: Ngày cấp | W3: Nơi cấp | X3: Email cá nhân | Y3: Email cấp quản lý | Z3: Hồ sơ giảm trừ gia cảnh | AD3: Mã số thuế cá nhân | AF3: Maritimebank (1. MSB) | AJ3: Ngân hàng khác hệ thống MSB (2. TPB; 3. VCB) | AN3: Ngân hàng ưu tiên thanh toán
C4: Phòng | D4: Tên nhân viên (khôngdấu) | E4: Tên nhân viên | F4: VP | G4: Chức vụ | H4: Cấp bậc tháng trước | I4: Cấp bậc điều chỉnh trong tháng | J4: Ngày điều chỉnh | K4: Hợp đồng LD | L4: Bắt đầu CTV/TT | M4: Bắt đầu Thử việc | N4: Bắt đầu Chính thức | O4: Ngày nghỉ việc | P4: Ngày sinh | Q4: Giới tính | R4: Số điện thoại | S4: Hộ khẩu | T4: Nơi tạm trú/Chỗ ở hiện tại | U4: CMND | V4: Ngày cấp | W4: Nơi cấp | X4: Email cá nhân | Y4: Email cấp quản lý | Z4: Số người phụ thuộc | AA4: Tháng bắt đầu giảm trừ | AB4: Tháng kết thúc giảm trừ | AC4: Tình trạng nộp hồ sơ GTGC | AD4: Mã số thuế cá nhân | AE4: Đơn vị cấp | AF4: Tài khoản thụ hưởng | AG4: Tên người thụ hưởng | AH4: Mã chi nhánh Ngân hàng thụ hưởng | AI4: Chi nhánh | AJ4: Số TK | AK4: Tên TK | AL4: Mã Chi nhánh theo MSB | AM4: Chi nhánh | AN4: Thông tin ngân hàng ưu tiên thanh toán | AO4: Số TK | AP4: Tên TK | AQ4: Mã Chi nhánh theo MSB | AR4: Chi nhánh | AS4: Ghi chú
B5: 1 | C5: 2 | D5: 3 | E5: 4 | F5: 5 | G5: 6 | H5: 7 | I5: 8 | J5: 9 | K5: 10 | L5: 11 | M5: 12 | N5: 13 | O5: 14 | P5: 15 | Q5: 16 | R5: 17 | S5: 18 | T5: 19 | U5: 20 | V5: 21 | W5: 22 | X5: 23 | Y5: 24 | Z5: 25 | AA5: 26 | AB5: 27 | AC5: 28 | AD5: 29 | AE5: 30 | AF5: 31 | AG5: 32 | AH5: 33 | AI5: 34 | AJ5: 35 | AK5: 36 | AL5: 37 | AM5: 38 | AN5: 39 | AO5: 40 | AP5: 41 | AQ5: 42 | AR5: 43 | AS5: 44
A6: 1 | B6: ADS01 | C6: BD01 HN | D6: NguyenVanA | E6: Nguyễn Văn A | F6: HN | G6: Trưởng phòng | H6: TP C1 | K6: CT | L6: 0 | M6: 42736 | N6: 42795 | O6: 0 | P6: 32143 | Q6: Nam | R6: 123456789 | S6: HN | T6: CG HN | U6: 1001 | V6: 36526 | W6: HN | X6: anv@novaon.vn | Y6: bom@novaon.vn | Z6: 1 | AA6: 1 | AB6: 0 | AC6: Đã nộp | AD6: 2001 | AE6: HN | AF6: MSB001 | AG6: Nguyễn Văn A | AH6: KHA | AI6: HN | AJ6: TPB001 | AK6: Nguyễn Văn A | AL6: KHB | AM6: HN | AN6: 2. TPB | AO6: =AJ6 -> TPB001 | AP6: =AK6 -> Nguyễn Văn A | AQ6: =AL6 -> KHB | AR6: =AM6 -> HN
A7: 2 | B7: ADS02 | C7: BD01 HN | D7: NguyenVanB | E7: Nguyễn Văn B | F7: HN | G7: Nhân viên | H7: C1 | K7: CT | L7: 0 | M7: 42736 | N7: 42795 | O7: 0 | P7: 32143 | Q7: Nam | R7: 23456789 | S7: HN | T7: CG HN | U7: 1002 | V7: 36527 | W7: HN | X7: bnv@novaon.vn | Y7: anv@novaon.vn | Z7: 2 | AA7: 2 | AB7: 0 | AC7: Đã nộp | AD7: 2002 | AE7: HN | AF7: MSB002 | AG7: Nguyễn Văn B | AH7: KHA | AI7: HN | AJ7: TPB002 | AK7: Nguyễn Văn B | AL7: KHB | AM7: HN | AN7: 2. TPB | AO7: =AJ7 -> TPB002 | AP7: =AK7 -> Nguyễn Văn B | AQ7: =AL7 -> KHB | AR7: =AM7 -> HN
A8: 3 | B8: ADS03 | C8: BD02 HN | D8: NguyenVanC | E8: Nguyễn Văn C | F8: HN | G8: Trưởng phòng | H8: TP C2 | K8: CT | L8: 0 | M8: 42736 | N8: 42795 | O8: 0 | P8: 32143 | Q8: Nam | R8: 3456789 | S8: HN | T8: CG HN | U8: 1003 | V8: 36528 | W8: HN | X8: cnv@novaon.vn | Y8: bom@novaon.vn | Z8: 3 | AA8: 3 | AB8: 0 | AC8: Đã nộp | AD8: 2003 | AE8: HN | AF8: MSB003 | AG8: Nguyễn Văn C | AH8: KHA | AI8: HN | AJ8: TPB003 | AK8: Nguyễn Văn C | AL8: KHB | AM8: HN | AN8: 2. TPB | AO8: =AJ8 -> TPB003 | AP8: =AK8 -> Nguyễn Văn C | AQ8: =AL8 -> KHB | AR8: =AM8 -> HN
A9: 4 | B9: ADS04 | C9: BD02 HN | D9: NguyenVanD | E9: Nguyễn Văn D | F9: HN | G9: Nhân viên | H9: C2 | K9: CT | L9: 0 | M9: 42736 | N9: 42795 | O9: 0 | P9: 32143 | Q9: Nam | R9: 456789 | S9: HN | T9: CG HN | U9: 1004 | V9: 36529 | W9: HN | X9: dnv@novaon.vn | Y9: cnv@novaon.vn | Z9: 4 | AA9: 4 | AB9: 0 | AC9: Đã nộp | AD9: 2004 | AE9: HN | AF9: MSB004 | AG9: Nguyễn Văn D | AH9: KHA | AI9: HN | AJ9: TPB004 | AK9: Nguyễn Văn D | AL9: KHB | AM9: HN | AN9: 2. TPB | AO9: =AJ9 -> TPB004 | AP9: =AK9 -> Nguyễn Văn D | AQ9: =AL9 -> KHB | AR9: =AM9 -> HN
A10: 5 | B10: ADS05 | C10: BD02 HN | D10: NguyenVanE | E10: Nguyễn Văn E | F10: HN | G10: Nhân viên | H10: C3 | K10: CT | L10: 0 | M10: 42736 | N10: 42795 | O10: 0 | P10: 32143 | Q10: Nam | R10: 56789 | S10: HN | T10: CG HN | U10: 1005 | V10: 36530 | W10: HN | X10: env@novaon.vn | Y10: cnv@novaon.vn | Z10: 5 | AA10: 5 | AB10: 0 | AC10: Đã nộp | AD10: 2005 | AE10: HN | AF10: MSB005 | AG10: Nguyễn Văn E | AH10: KHA | AI10: HN | AJ10: TPB005 | AK10: Nguyễn Văn E | AL10: KHB | AM10: HN | AN10: 2. TPB | AO10: =AJ10 -> TPB005 | AP10: =AK10 -> Nguyễn Văn E | AQ10: =AL10 -> KHB | AR10: =AM10 -> HN
A11: 6 | B11: ADS06 | C11: BD03 SG | D11: NguyenVanF | E11: Nguyễn Văn F | F11: HCM | G11: Trưởng phòng | H11: TP C3 | K11: CT | L11: 0 | M11: 42736 | N11: 42795 | O11: 0 | P11: 32143 | Q11: Nam | R11: 6789 | S11: HN | T11: CG HN | U11: 1006 | V11: 36531 | W11: HN | X11: fnv@novaon.vn | Y11: bom@novaon.vn | Z11: 6 | AA11: 6 | AB11: 0 | AC11: Đã nộp | AD11: 2006 | AE11: HN | AF11: MSB006 | AG11: Nguyễn Văn F | AH11: KHA | AI11: HN | AJ11: TPB006 | AK11: Nguyễn Văn F | AL11: KHB | AM11: HN | AN11: 2. TPB | AO11: =AJ11 -> TPB006 | AP11: =AK11 -> Nguyễn Văn F | AQ11: =AL11 -> KHB | AR11: =AM11 -> HN
A12: 7 | B12: ADS07 | C12: BD03 SG | D12: NguyenVanG | E12: Nguyễn Văn G | F12: HCM | G12: Nhân viên | H12: C4 | K12: CT | L12: 0 | M12: 42736 | N12: 42795 | O12: 0 | P12: 32143 | Q12: Nam | R12: 789 | S12: HN | T12: CG HN | U12: 1007 | V12: 36532 | W12: HN | X12: gnv@novaon.vn | Y12: fnv@novaon.vn | Z12: 7 | AA12: 7 | AB12: 0 | AC12: Đã nộp | AD12: 2007 | AE12: HN | AF12: MSB007 | AG12: Nguyễn Văn G | AH12: KHA | AI12: HN | AJ12: TPB007 | AK12: Nguyễn Văn G | AL12: KHB | AM12: HN | AN12: 2. TPB | AO12: =AJ12 -> TPB007 | AP12: =AK12 -> Nguyễn Văn G | AQ12: =AL12 -> KHB | AR12: =AM12 -> HN
A13: 8 | B13: ADS08 | C13: BD03 SG | D13: NguyenVanH | E13: Nguyễn Văn H | F13: HCM | G13: Nhân viên | H13: S1 | K13: CT | L13: 0 | M13: 42736 | N13: 42795 | O13: 0 | P13: 32143 | Q13: Nam | R13: 89 | S13: HN | T13: CG HN | U13: 1008 | V13: 36533 | W13: HN | X13: hnv@novaon.vn | Y13: fnv@novaon.vn | Z13: 8 | AA13: 8 | AB13: 0 | AC13: Đã nộp | AD13: 2008 | AE13: HN | AF13: MSB008 | AG13: Nguyễn Văn H | AH13: KHA | AI13: HN | AJ13: TPB008 | AK13: Nguyễn Văn H | AL13: KHB | AM13: HN | AN13: 2. TPB | AO13: =AJ13 -> TPB008 | AP13: =AK13 -> Nguyễn Văn H | AQ13: =AL13 -> KHB | AR13: =AM13 -> HN
A14: 9 | B14: ADS09 | C14: HR HN | D14: NguyenVanI | E14: Nguyễn Văn I | F14: HN | G14: Trưởng phòng | H14: TP KPC | K14: CT | L14: 0 | M14: 42736 | N14: 42795 | O14: 0 | P14: 32143 | Q14: Nam | R14: 9 | S14: HN | T14: CG HN | U14: 1009 | V14: 36534 | W14: HN | X14: inv@novaon.vn | Y14: bom@novaon.vn | Z14: 9 | AA14: 9 | AB14: 0 | AC14: Đã nộp | AD14: 2009 | AE14: HN | AF14: MSH009 | AG14: Nguyễn Văn I | AH14: KHA | AI14: HN | AJ14: TPB009 | AK14: Nguyễn Văn I | AL14: KHB | AM14: HN | AN14: 2. TPB | AO14: =AJ14 -> TPB009 | AP14: =AK14 -> Nguyễn Văn I | AQ14: =AL14 -> KHB | AR14: =AM14 -> HN
A15: 10 | B15: ADS10 | C15: HR HN | D15: NguyenVanK | E15: Nguyễn Văn K | F15: HN | G15: Nhân viên | H15: C1 | K15: CT | L15: 0 | M15: 42736 | N15: 42795 | O15: 0 | P15: 32143 | Q15: Nam | R15: 10 | S15: HN | T15: CG HN | U15: 1010 | V15: 36535 | W15: HN | X15: knv@novaon.vn | Y15: inv@novaon.vn | Z15: 10 | AA15: 10 | AB15: 0 | AC15: Đã nộp | AD15: 2010 | AE15: HN | AF15: MSH0010 | AG15: Nguyễn Văn K | AH15: KHA | AI15: HN | AJ15: TPB010 | AK15: Nguyễn Văn K | AL15: KHB | AM15: HN | AN15: 2. TPB | AO15: =AJ15 -> TPB010 | AP15: =AK15 -> Nguyễn Văn K | AQ15: =AL15 -> KHB | AR15: =AM15 -> HN

Sheet 1.2 HR-Data luong
A1: Ngày đủ công trong tháng: | D1: 22.5 | P1: ERP | Q1: ERP | R1: ERP | AA1: ERP | AB1: ERP | AC1: ERP
A2: STT | B2: MA NHAN VIEN | C2: PHONG | D2: TEN NHAN VIEN (KO DAU) | E2: TEN NHAN VIEN | F2: VP | G2: CHUC VU | H2: CAP BAC | I2: HD | J2: EMAIL | K2: Email cấp quản lý | L2: MUC LUONG HUONG | P2: CHAM CONG | S2: MUC DONG BHXH | W2: Phụ cấp thâm niên | AA2: Công tính % thâm niên | AD2: HO TRO LATOP | AF2: PHỤ CẤP BD | AH2: Phụ cấp theo ngày công thực tế | AL2: Phạt | AQ2: BHXH | AT2: BHYT | AW2: BHTN | AZ2: KPCĐ | BC2: Tổng khấu trừ nhân viên | BD2: Tổng Công ty chi trả | BE2: Quỹ văn hóa | BF2: Nghỉ việc | BG2: Ghi chú - Hoãn thanh toán lương
L3: LUONG THANG TRUOC | M3: LUONG DIEU CHINH | N3: NGAY DIEU CHINH | O3: NOI DUNG DIEU CHINH | P3: Tổng ngày công hưởng lương | R3: Tổng | S3: LUONG THANG TRUOC | T3: LUONG DIEU CHINH | U3: NGAY DIEU CHINH | V3: NOI DUNG DIEU CHINH | W3: % được hưởng tháng trước | X3: % điều chỉnh | Y3: Ngày điều chỉnh | Z3: Nội dung điều chỉnh | AA3: Tổng ngày công hưởng lương | AC3: Tổng | AD3: Mức hỗ trợ | AE3: Số ngày hỗ trợ | AF3: Mức hỗ trợ | AG3: Số ngày hỗ trợ | AH3: Phụ cấp xăng xe | AI3: Phụ cấp điện thoại | AJ3: Phụ cấp khác | AK3: Tổng phụ cấp | AL3: Phạt đi muộn | AN3: Phạt khác | AP3: Tổng phạt | AQ3: Nhân viên đóng | AR3: Công ty chi trả | AS3: Tổng | AT3: Nhân viên đóng | AU3: Công ty chi trả | AV3: Tổng | AW3: Nhân viên đóng | AX3: Công ty chi trả | AY3: Tổng | AZ3: Nhân viên đóng | BA3: Công ty chi trả | BB3: Tổng
C4: Phòng | D4: Tên nhân viên (khôngdấu) | E4: Tên nhân viên | F4: VP | G4: Chức vụ | H4: Cấp bậc | I4: Hợp đồng LD | J4: Email cấp quản lý | K4: Email cấp quản lý | P4: Trước điều chỉnh | Q4: Sau điều chỉnh | AA4: Trước điều chỉnh | AB4: Sau điều chỉnh | AH4: Phụ cấp xăng xe, điện thoại | AI4: Phụ cấp xăng xe, điện thoại | AJ4: Phụ cấp khác | AL4: Số phút | AM4: Tiền phạt | AN4: Số tiền | AO4: Lý do | AQ4: 0.08 | AR4: 0.175 | AT4: 0.015 | AU4: 0.03 | AW4: 0.01 | AX4: 0.01 | AZ4: 0.01 | BA4: 0.02
A5: # | B5: 1 | C5: 2 | D5: 3 | E5: 4 | F5: 5 | G5: 6 | H5: 7 | I5: 8 | J5: 9 | K5: 10 | L5: 11 | M5: 12 | N5: 13 | O5: 14 | P5: 15 | Q5: 16 | R5: 17 | S5: 18 | T5: 19 | U5: 20 | V5: 21 | W5: 22 | X5: 23 | Y5: 24 | Z5: 25 | AA5: 26 | AB5: 27 | AC5: 28 | AD5: 29 | AE5: 30 | AF5: 31 | AG5: 32 | AH5: 33 | AI5: 34 | AJ5: 35 | AK5: 36 | AL5: 37 | AM5: 38 | AN5: 39 | AO5: 40 | AP5: 41 | AQ5: 42 | AR5: 43 | AS5: 44 | AT5: 45 | AU5: 46 | AV5: 47 | AW5: 48 | AX5: 49 | AY5: 50 | AZ5: 51 | BA5: 52 | BB5: 53 | BC5: 54 | BD5: 55 | BE5: 56 | BF5: 57 | BG5: 58
A6: 1 | B6: ADS01 | C6: BD01 HN | D6: NguyenVanA | E6: Nguyễn Văn A | F6: HN | G6: Trưởng phòng | H6: TP C1 | I6: CT | J6: anv@novaon.vn | K6: bom@novaon.vn | L6: 1000000 | M6: 5000000 | N6: 42919 | O6: Tăng lương do tăng cấp | P6: 4 | Q6: 18.5 | R6: 20.5 | S6: 1000000 | T6: 0 | U6: 0 | V6: 0 | W6: 0.01 | X6: 0.02 | Y6: 42917 | Z6: Đủ 3 năm công tác | AA6: 2 | AB6: 20.5 | AC6: =SUM(AA6:AB6) -> 22.5 | AD6: 200000 | AE6: 15 | AF6: 200000 | AG6: 15 | AH6: 0 | AI6: 0 | AJ6: 500000 | AK6: 500000 | AL6: 16 | AM6: 0 | AN6: 0 | AO6: 0 | AP6: =SUM(AM6:AN6) -> 0 | AQ6: 520000 | AR6: 1170000 | AS6: 1690000 | AT6: 97500 | AU6: 195000 | AV6: 292500 | AW6: 65000 | AX6: 65000 | AY6: 130000 | AZ6: 65000 | BA6: 130000 | BB6: 195000 | BC6: =SUM(AQ6,AT6,AW6,AZ6) -> 747500 | BD6: =SUM(AR6,AU6,AX6,BA6) -> 1560000 | BE6: 0 | BF6: ON
A7: 2 | B7: ADS02 | C7: BD01 HN | D7: NguyenVanB | E7: Nguyễn Văn B | F7: HN | G7: Nhân viên | H7: C1 | I7: CT | J7: bnv@novaon.vn | K7: anv@novaon.vn | L7: 2000000 | M7: 0 | N7: 0 | O7: 0 | P7: 22.5 | R7: 20.5 | S7: 2000000 | T7: 0 | U7: 0 | V7: 0 | W7: 0.02 | X7: 0 | Y7: 0 | Z7: 0 | AA7: 22.5 | AC7: =SUM(AA7:AB7) -> 22.5 | AD7: 200000 | AE7: 15 | AF7: 200000 | AG7: 15 | AH7: 0 | AI7: 0 | AJ7: 500000 | AK7: 500000 | AL7: 0 | AM7: 0 | AN7: 1000000 | AO7: Đi họp muộn | AP7: =SUM(AM7:AN7) -> 1000000 | AQ7: 376000 | AR7: 846000 | AS7: 1222000 | AT7: 70500 | AU7: 141000 | AV7: 211500 | AW7: 47000 | AX7: 47000 | AY7: 94000 | AZ7: 47000 | BA7: 94000 | BB7: 141000 | BC7: =SUM(AQ7,AT7,AW7,AZ7) -> 540500 | BD7: =SUM(AR7,AU7,AX7,BA7) -> 1128000 | BE7: 0 | BF7: OFF
A8: 3 | B8: ADS03 | C8: BD02 HN | D8: NguyenVanC | E8: Nguyễn Văn C | F8: HN | G8: Trưởng phòng | H8: TP C2 | I8: CT | J8: cnv@novaon.vn | K8: bom@novaon.vn | L8: 3000000 | M8: 0 | N8: 0 | O8: 0 | P8: 22.5 | R8: 20.5 | S8: 3000000 | T8: 0 | U8: 0 | V8: 0 | W8: 0.03 | X8: 0 | Y8: 0 | Z8: 0 | AA8: 22.5 | AC8: =SUM(AA8:AB8) -> 22.5 | AD8: 200000 | AE8: 15 | AF8: 200000 | AG8: 15 | AH8: 0 | AI8: 0 | AJ8: 500000 | AK8: 500000 | AL8: 6 | AM8: 0 | AN8: 0 | AO8: 0 | AP8: =SUM(AM8:AN8) -> 0 | AQ8: 0 | AR8: 0 | AS8: 0 | AT8: 0 | AU8: 0 | AV8: 0 | AW8: 0 | AX8: 0 | AY8: 0 | AZ8: 0 | BA8: 0 | BB8: 0 | BC8: =SUM(AQ8,AT8,AW8,AZ8) -> 0 | BD8: =SUM(AR8,AU8,AX8,BA8) -> 0 | BE8: 30000 | BF8: ON
A9: 4 | B9: ADS04 | C9: BD02 HN | D9: NguyenVanD | E9: Nguyễn Văn D | F9: HN | G9: Nhân viên | H9: C2 | I9: CT | J9: dnv@novaon.vn | K9: cnv@novaon.vn | L9: 4000000 | M9: 0 | N9: 0 | O9: 0 | P9: 22.5 | R9: 20.5 | S9: 4000000 | T9: 0 | U9: 0 | V9: 0 | W9: 0.04 | X9: 0 | Y9: 0 | Z9: 0 | AA9: 22.5 | AC9: =SUM(AA9:AB9) -> 22.5 | AD9: 200000 | AE9: 15 | AF9: 200000 | AG9: 15 | AH9: 0 | AI9: 0 | AJ9: 500000 | AK9: 500000 | AL9: 0 | AM9: 0 | AN9: 0 | AO9: 0 | AP9: =SUM(AM9:AN9) -> 0 | AQ9: 321200 | AR9: 722700 | AS9: 1043900 | AT9: 60225 | AU9: 120450 | AV9: 180675 | AW9: 40150 | AX9: 40150 | AY9: 80300 | AZ9: 40150 | BA9: 80300 | BB9: 120450 | BC9: =SUM(AQ9,AT9,AW9,AZ9) -> 461725 | BD9: =SUM(AR9,AU9,AX9,BA9) -> 963600 | BE9: 0 | BF9: ON
A10: 5 | B10: ADS05 | C10: BD02 HN | D10: NguyenVanE | E10: Nguyễn Văn E | F10: HN | G10: Nhân viên | H10: C3 | I10: CT | J10: env@novaon.vn | K10: cnv@novaon.vn | L10: 5000000 | M10: 10000000 | N10: 42917 | O10: Tăng lương do tăng cấp | P10: 2 | Q10: 20.5 | R10: 20.5 | S10: 5000000 | T10: 6000000 | U10: 42917 | V10: Tăng lương do tăng cấp | W10: 0.05 | X10: 0.06 | Y10: 42916 | Z10: Đủ 3 năm công tác | AA10: 1 | AB10: 21.5 | AC10: =SUM(AA10:AB10) -> 22.5 | AD10: 200000 | AE10: 22.5 | AF10: 200000 | AG10: 22.5 | AH10: 0 | AI10: 0 | AJ10: 0 | AK10: 0 | AL10: 8 | AM10: 0 | AN10: 0 | AO10: 0 | AP10: =SUM(AM10:AN10) -> 0 | AQ10: 321200 | AR10: 722700 | AS10: 1043900 | AT10: 60225 | AU10: 120450 | AV10: 180675 | AW10: 40150 | AX10: 40150 | AY10: 80300 | AZ10: 40150 | BA10: 80300 | BB10: 120450 | BC10: =SUM(AQ10,AT10,AW10,AZ10) -> 461725 | BD10: =SUM(AR10,AU10,AX10,BA10) -> 963600 | BE10: 0 | BF10: ON
A11: 6 | B11: ADS06 | C11: BD03 SG | D11: NguyenVanF | E11: Nguyễn Văn F | F11: HCM | G11: Trưởng phòng | H11: TP C3 | I11: CT | J11: fnv@novaon.vn | K11: bom@novaon.vn | L11: 6000000 | M11: 0 | N11: 0 | O11: 0 | P11: 22.5 | R11: =SUM(P11:Q11) -> 22.5 | S11: 6000000 | T11: 0 | U11: 0 | V11: 0 | W11: 0.06 | X11: 0 | Y11: 0 | Z11: 0 | AA11: 22.5 | AC11: =SUM(AA11:AB11) -> 22.5 | AD11: 200000 | AE11: 22.5 | AF11: 200000 | AG11: 22.5 | AH11: 0 | AI11: 0 | AJ11: 0 | AK11: 0 | AL11: 0 | AM11: 0 | AN11: 0 | AO11: 0 | AP11: =SUM(AM11:AN11) -> 0 | AQ11: 0 | AR11: 0 | AS11: 0 | AT11: 0 | AU11: 0 | AV11: 0 | AW11: 0 | AX11: 0 | AY11: 0 | AZ11: 0 | BA11: 0 | BB11: 0 | BC11: =SUM(AQ11,AT11,AW11,AZ11) -> 0 | BD11: =SUM(AR11,AU11,AX11,BA11) -> 0 | BE11: 0 | BF11: ON
A12: 7 | B12: ADS07 | C12: BD03 SG | D12: NguyenVanG | E12: Nguyễn Văn G | F12: HCM | G12: Nhân viên | H12: C4 | I12: CT | J12: gnv@novaon.vn | K12: fnv@novaon.vn | L12: 7000000 | M12: 0 | N12: 0 | O12: 0 | P12: 22.5 | R12: =SUM(P12:Q12) -> 22.5 | S12: 7000000 | T12: 0 | U12: 0 | V12: 0 | W12: 0.07 | X12: 0 | Y12: 0 | Z12: 0 | AA12: 22.5 | AC12: =SUM(AA12:AB12) -> 22.5 | AD12: 200000 | AE12: 22.5 | AF12: 200000 | AG12: 22.5 | AH12: 0 | AI12: 0 | AJ12: 0 | AK12: 0 | AL12: 0 | AM12: 0 | AN12: 0 | AO12: 0 | AP12: =SUM(AM12:AN12) -> 0 | AQ12: 321200 | AR12: 722700 | AS12: 1043900 | AT12: 60225 | AU12: 120450 | AV12: 180675 | AW12: 40150 | AX12: 40150 | AY12: 80300 | AZ12: 40150 | BA12: 80300 | BB12: 120450 | BC12: =SUM(AQ12,AT12,AW12,AZ12) -> 461725 | BD12: =SUM(AR12,AU12,AX12,BA12) -> 963600 | BE12: 0 | BF12: ON
A13: 8 | B13: ADS08 | C13: BD03 SG | D13: NguyenVanH | E13: Nguyễn Văn H | F13: HCM | G13: Nhân viên | H13: S1 | I13: CT | J13: hnv@novaon.vn | K13: fnv@novaon.vn | L13: 8000000 | M13: 10000000 | N13: 42931 | O13: Tăng lương do tăng cấp | P13: 10 | Q13: 12.5 | R13: =SUM(P13:Q13) -> 22.5 | S13: 8000000 | T13: 10000000 | U13: 42917 | V13: Vào chính thức | W13: 0.08 | X13: 0.09 | Y13: 42933 | Z13: Đủ 3 năm công tác | AA13: 12 | AB13: 10.5 | AC13: =SUM(AA13:AB13) -> 22.5 | AD13: 200000 | AE13: 22.5 | AF13: 200000 | AG13: 22.5 | AH13: 0 | AI13: 0 | AJ13: 0 | AK13: 0 | AL13: 9 | AM13: 0 | AN13: 0 | AO13: 0 | AP13: =SUM(AM13:AN13) -> 0 | AQ13: 321200 | AR13: 722700 | AS13: 1043900 | AT13: 60225 | AU13: 120450 | AV13: 180675 | AW13: 40150 | AX13: 40150 | AY13: 80300 | AZ13: 40150 | BA13: 80300 | BB13: 120450 | BC13: =SUM(AQ13,AT13,AW13,AZ13) -> 461725 | BD13: =SUM(AR13,AU13,AX13,BA13) -> 963600 | BE13: 0 | BF13: ON
A14: 9 | B14: ADS09 | C14: HR HN | D14: NguyenVanI | E14: Nguyễn Văn I | F14: HN | G14: Trưởng phòng | H14: TP KPC | I14: CT | J14: inv@novaon.vn | K14: bom@novaon.vn | L14: 9000000 | M14: 0 | N14: 0 | O14: 0 | P14: 22.5 | R14: =SUM(P14:Q14) -> 22.5 | S14: 9000000 | T14: 0 | U14: 0 | V14: 0 | W14: 0.09 | X14: 0 | Y14: 0 | Z14: 0 | AA14: 22.5 | AC14: =SUM(AA14:AB14) -> 22.5 | AD14: 200000 | AE14: 22.5 | AF14: 200000 | AG14: 22.5 | AH14: 0 | AI14: 0 | AJ14: 0 | AK14: 0 | AL14: 32 | AM14: 22000 | AN14: 0 | AO14: 0 | AP14: =SUM(AM14:AN14) -> 22000 | AQ14: 321200 | AR14: 722700 | AS14: 1043900 | AT14: 60225 | AU14: 120450 | AV14: 180675 | AW14: 40150 | AX14: 40150 | AY14: 80300 | AZ14: 40150 | BA14: 80300 | BB14: 120450 | BC14: =SUM(AQ14,AT14,AW14,AZ14) -> 461725 | BD14: =SUM(AR14,AU14,AX14,BA14) -> 963600 | BE14: 0 | BF14: ON
A15: 10 | B15: ADS10 | C15: HR HN | D15: NguyenVanK | E15: Nguyễn Văn K | F15: HN | G15: Nhân viên | H15: C1 | I15: CT | J15: knv@novaon.vn | K15: inv@novaon.vn | L15: 10000000 | M15: 0 | N15: 0 | O15: 0 | P15: 22.5 | R15: =SUM(P15:Q15) -> 22.5 | S15: 10000000 | T15: 0 | U15: 0 | V15: 0 | W15: 0.1 | X15: 0 | Y15: 0 | Z15: 0 | AA15: 22.5 | AC15: =SUM(AA15:AB15) -> 22.5 | AD15: 200000 | AE15: 22.5 | AF15: 200000 | AG15: 22.5 | AH15: 0 | AI15: 0 | AJ15: 0 | AK15: 0 | AL15: 0 | AM15: 0 | AN15: 0 | AO15: 0 | AP15: =SUM(AM15:AN15) -> 0 | AQ15: 321200 | AR15: 722700 | AS15: 1043900 | AT15: 60225 | AU15: 120450 | AV15: 180675 | AW15: 40150 | AX15: 40150 | AY15: 80300 | AZ15: 40150 | BA15: 80300 | BB15: 120450 | BC15: =SUM(AQ15,AT15,AW15,AZ15) -> 461725 | BD15: =SUM(AR15,AU15,AX15,BA15) -> 963600 | BE15: 0 | BF15: ON

Sheet 2.1 KT-Update ty le
A1: Tỷ lệ trích các khoản bảo hiểm bắt buộc theo lương đóng BH
A2: Loại BH | B2: Công ty | C2: Nhân viên | D2: Tổng
A3: BHXH | B3: 0.175 | C3: 0.08 | D3: =SUM(B3:C3) -> 0.255
A4: BHYT | B4: 0.03 | C4: 0.015 | D4: =SUM(B4:C4) -> 0.045
A5: BHTN | B5: 0.01 | C5: 0.01 | D5: =SUM(B5:C5) -> 0.02
A6: KPCD | B6: 0.02 | C6: 0.01 | D6: =SUM(B6:C6) -> 0.03
A7: Tổng | B7: =SUM(B3:B6) -> 0.235 | C7: =SUM(C3:C6) -> 0.115 | D7: =SUM(B7:C7) -> 0.35
A9: Biểu thuế TNCN lũy tiến từng phần
A10: Mức thu nhập chịu thuế đến | B10: Thuế suất | C10: Lũy tiến | D10: Toàn phần | E10: Mức trừ
A11: 5000000 | B11: 0.05 | C11: =A11*B11 -> 250000 | D11: =A11*B11 -> 250000 | E11: =D11-C11 -> 0
A12: 10000000 | B12: 0.1 | C12: =C11+(A12-A11)*B12 -> 750000 | D12: =A12*B12 -> 1000000 | E12: =D12-C12 -> 250000
A13: 18000000 | B13: 0.15 | C13: =C12+(A13-A12)*B13 -> 1950000 | D13: =A13*B13 -> 2700000 | E13: =D13-C13 -> 750000
A14: 32000000 | B14: 0.2 | C14: =C13+(A14-A13)*B14 -> 4750000 | D14: =A14*B14 -> 6400000 | E14: =D14-C14 -> 1650000
A15: 52000000 | B15: 0.25 | C15: =C14+(A15-A14)*B15 -> 9750000 | D15: =A15*B15 -> 13000000 | E15: =D15-C15 -> 3250000
A16: 80000000 | B16: 0.3 | C16: =C15+(A16-A15)*B16 -> 18150000 | D16: =A16*B16 -> 24000000 | E16: =D16-C16 -> 5850000
A17: > 80,000,000 | B17: 0.35 | C17: =C16 -> 18150000 | D17: =A16*B17 -> 28000000 | E17: =D17-C17 -> 9850000
A19: Mức giảm trừ thuế TNCN
A20: Tiền ăn ca | B20: 600000
A21: Giảm trừ bản thân | B21: 9000000
A22: Giảm trừ gia cảnh | B22: 3600000

Sheet 2.2 KT-THUONG
A1: Bảng tính thưởng
A3: Mã cty | B3: TT | C3: Mã NV | D3: Phòng | E3: HO TEN | F3: Họ tên | G3: VP | H3: Chức vụ | I3: Cấp bậc | J3: Loai HDLD | K3: Lương khác
K4: Hỗ trợ xăng xe điện thoại | L4: Thưởng MG | M4: Thưởng hiệu quả công việc | N4: Lương hiệu quả | O4: Lương tháng 13 | P4: Thưởng có thuế khác […] | Q4: Thưởng KPI (không thuế) | R4: Thưởng không thuế khác […]
C5: 1 | D5: 2 | E5: 3 | F5: 4 | G5: 5 | H5: 6 | I5: 7 | J5: 8 | K5: 9 | L5: 10 | M5: 11 | N5: 12 | O5: 13 | P5: 14 | Q5: 15 | R5: 16
A6: ADS | B6: 1 | C6: =VLOOKUP(B6,'1.2 HR-Data luong'!A:B,2,0) -> ADS01 | D6: =VLOOKUP($C6,'1.2 HR-Data luong'!$B:$BG,D$5,0) -> BD01 HN | E6: =VLOOKUP($C6,'1.2 HR-Data luong'!$B:$BG,E$5,0) -> NguyenVanA | F6: =VLOOKUP($C6,'1.2 HR-Data luong'!$B:$BG,F$5,0) -> Nguyễn Văn A | G6: =VLOOKUP($C6,'1.2 HR-Data luong'!$B:$BG,G$5,0) -> HN | H6: =VLOOKUP($C6,'1.2 HR-Data luong'!$B:$BG,H$5,0) -> Trưởng phòng | I6: =VLOOKUP($C6,'1.2 HR-Data luong'!$B:$BG,I$5,0) -> TP C1 | J6: =VLOOKUP($C6,'1.2 HR-Data luong'!$B:$BG,J$5,0) -> CT | K6: 300000 | L6: 1000000 | M6: 100000 | N6: 2000000 | O6: 10000000 | P6: 0 | Q6: 50000000
A7: ADS | B7: 2 | C7: =VLOOKUP(B7,'1.2 HR-Data luong'!A:B,2,0) -> ADS02 | D7: =VLOOKUP($C7,'1.2 HR-Data luong'!$B:$BG,D$5,0) -> BD01 HN | E7: =VLOOKUP($C7,'1.2 HR-Data luong'!$B:$BG,E$5,0) -> NguyenVanB | F7: =VLOOKUP($C7,'1.2 HR-Data luong'!$B:$BG,F$5,0) -> Nguyễn Văn B | G7: =VLOOKUP($C7,'1.2 HR-Data luong'!$B:$BG,G$5,0) -> HN | H7: =VLOOKUP($C7,'1.2 HR-Data luong'!$B:$BG,H$5,0) -> Nhân viên | I7: =VLOOKUP($C7,'1.2 HR-Data luong'!$B:$BG,I$5,0) -> C1 | J7: =VLOOKUP($C7,'1.2 HR-Data luong'!$B:$BG,J$5,0) -> CT | K7: 300000 | L7: 2000000 | M7: 200000 | N7: 0 | O7: 20000000 | P7: 0 | Q7: 50000000
A8: ADS | B8: 3 | C8: =VLOOKUP(B8,'1.2 HR-Data luong'!A:B,2,0) -> ADS03 | D8: =VLOOKUP($C8,'1.2 HR-Data luong'!$B:$BG,D$5,0) -> BD02 HN | E8: =VLOOKUP($C8,'1.2 HR-Data luong'!$B:$BG,E$5,0) -> NguyenVanC | F8: =VLOOKUP($C8,'1.2 HR-Data luong'!$B:$BG,F$5,0) -> Nguyễn Văn C | G8: =VLOOKUP($C8,'1.2 HR-Data luong'!$B:$BG,G$5,0) -> HN | H8: =VLOOKUP($C8,'1.2 HR-Data luong'!$B:$BG,H$5,0) -> Trưởng phòng | I8: =VLOOKUP($C8,'1.2 HR-Data luong'!$B:$BG,I$5,0) -> TP C2 | J8: =VLOOKUP($C8,'1.2 HR-Data luong'!$B:$BG,J$5,0) -> CT | K8: 300000 | L8: 3000000 | M8: 300000 | N8: 0 | O8: 30000000 | P8: 0 | Q8: 50000000
A9: ADS | B9: 4 | C9: =VLOOKUP(B9,'1.2 HR-Data luong'!A:B,2,0) -> ADS04 | D9: =VLOOKUP($C9,'1.2 HR-Data luong'!$B:$BG,D$5,0) -> BD02 HN | E9: =VLOOKUP($C9,'1.2 HR-Data luong'!$B:$BG,E$5,0) -> NguyenVanD | F9: =VLOOKUP($C9,'1.2 HR-Data luong'!$B:$BG,F$5,0) -> Nguyễn Văn D | G9: =VLOOKUP($C9,'1.2 HR-Data luong'!$B:$BG,G$5,0) -> HN | H9: =VLOOKUP($C9,'1.2 HR-Data luong'!$B:$BG,H$5,0) -> Nhân viên | I9: =VLOOKUP($C9,'1.2 HR-Data luong'!$B:$BG,I$5,0) -> C2 | J9: =VLOOKUP($C9,'1.2 HR-Data luong'!$B:$BG,J$5,0) -> CT | K9: 300000 | L9: 4000000 | M9: 400000 | N9: 0 | O9: 40000000 | P9: 0 | Q9: 50000000
A10: ADS | B10: 5 | C10: =VLOOKUP(B10,'1.2 HR-Data luong'!A:B,2,0) -> ADS05 | D10: =VLOOKUP($C10,'1.2 HR-Data luong'!$B:$BG,D$5,0) -> BD02 HN | E10: =VLOOKUP($C10,'1.2 HR-Data luong'!$B:$BG,E$5,0) -> NguyenVanE | F10: =VLOOKUP($C10,'1.2 HR-Data luong'!$B:$BG,F$5,0) -> Nguyễn Văn E | G10: =VLOOKUP($C10,'1.2 HR-Data luong'!$B:$BG,G$5,0) -> HN | H10: =VLOOKUP($C10,'1.2 HR-Data luong'!$B:$BG,H$5,0) -> Nhân viên | I10: =VLOOKUP($C10,'1.2 HR-Data luong'!$B:$BG,I$5,0) -> C3 | J10: =VLOOKUP($C10,'1.2 HR-Data luong'!$B:$BG,J$5,0) -> CT | K10: 300000 | L10: 5000000 | M10: 500000 | N10: 0 | O10: 50000000 | P10: 0 | Q10: 50000000
A11: ADS | B11: 6 | C11: =VLOOKUP(B11,'1.2 HR-Data luong'!A:B,2,0) -> ADS06 | D11: =VLOOKUP($C11,'1.2 HR-Data luong'!$B:$BG,D$5,0) -> BD03 SG | E11: =VLOOKUP($C11,'1.2 HR-Data luong'!$B:$BG,E$5,0) -> NguyenVanF | F11: =VLOOKUP($C11,'1.2 HR-Data luong'!$B:$BG,F$5,0) -> Nguyễn Văn F | G11: =VLOOKUP($C11,'1.2 HR-Data luong'!$B:$BG,G$5,0) -> HCM | H11: =VLOOKUP($C11,'1.2 HR-Data luong'!$B:$BG,H$5,0) -> Trưởng phòng | I11: =VLOOKUP($C11,'1.2 HR-Data luong'!$B:$BG,I$5,0) -> TP C3 | J11: =VLOOKUP($C11,'1.2 HR-Data luong'!$B:$BG,J$5,0) -> CT | K11: 300000 | L11: 6000000 | M11: 600000 | N11: 0 | O11: 60000000 | P11: 0 | Q11: 50000000
A12: ADS | B12: 7 | C12: =VLOOKUP(B12,'1.2 HR-Data luong'!A:B,2,0) -> ADS07 | D12: =VLOOKUP($C12,'1.2 HR-Data luong'!$B:$BG,D$5,0) -> BD03 SG | E12: =VLOOKUP($C12,'1.2 HR-Data luong'!$B:$BG,E$5,0) -> NguyenVanG | F12: =VLOOKUP($C12,'1.2 HR-Data luong'!$B:$BG,F$5,0) -> Nguyễn Văn G | G12: =VLOOKUP($C12,'1.2 HR-Data luong'!$B:$BG,G$5,0) -> HCM | H12: =VLOOKUP($C12,'1.2 HR-Data luong'!$B:$BG,H$5,0) -> Nhân viên | I12: =VLOOKUP($C12,'1.2 HR-Data luong'!$B:$BG,I$5,0) -> C4 | J12: =VLOOKUP($C12,'1.2 HR-Data luong'!$B:$BG,J$5,0) -> CT | K12: 300000 | L12: 7000000 | M12: 700000 | N12: 0 | O12: 70000000 | P12: 0 | Q12: 50000000
A13: ADS | B13: 8 | C13: =VLOOKUP(B13,'1.2 HR-Data luong'!A:B,2,0) -> ADS08 | D13: =VLOOKUP($C13,'1.2 HR-Data luong'!$B:$BG,D$5,0) -> BD03 SG | E13: =VLOOKUP($C13,'1.2 HR-Data luong'!$B:$BG,E$5,0) -> NguyenVanH | F13: =VLOOKUP($C13,'1.2 HR-Data luong'!$B:$BG,F$5,0) -> Nguyễn Văn H | G13: =VLOOKUP($C13,'1.2 HR-Data luong'!$B:$BG,G$5,0) -> HCM | H13: =VLOOKUP($C13,'1.2 HR-Data luong'!$B:$BG,H$5,0) -> Nhân viên | I13: =VLOOKUP($C13,'1.2 HR-Data luong'!$B:$BG,I$5,0) -> S1 | J13: =VLOOKUP($C13,'1.2 HR-Data luong'!$B:$BG,J$5,0) -> CT | K13: 300000 | L13: 8000000 | M13: 800000 | N13: 0 | O13: 80000000 | P13: 0 | Q13: 50000000
A14: ADS | B14: 9 | C14: =VLOOKUP(B14,'1.2 HR-Data luong'!A:B,2,0) -> ADS09 | D14: =VLOOKUP($C14,'1.2 HR-Data luong'!$B:$BG,D$5,0) -> HR HN | E14: =VLOOKUP($C14,'1.2 HR-Data luong'!$B:$BG,E$5,0) -> NguyenVanI | F14: =VLOOKUP($C14,'1.2 HR-Data luong'!$B:$BG,F$5,0) -> Nguyễn Văn I | G14: =VLOOKUP($C14,'1.2 HR-Data luong'!$B:$BG,G$5,0) -> HN | H14: =VLOOKUP($C14,'1.2 HR-Data luong'!$B:$BG,H$5,0) -> Trưởng phòng | I14: =VLOOKUP($C14,'1.2 HR-Data luong'!$B:$BG,I$5,0) -> TP KPC | J14: =VLOOKUP($C14,'1.2 HR-Data luong'!$B:$BG,J$5,0) -> CT | K14: 300000 | L14: 9000000 | M14: 900000 | N14: 0 | O14: 90000000 | P14: 0 | Q14: 50000000
A15: ADS | B15: 10 | C15: =VLOOKUP(B15,'1.2 HR-Data luong'!A:B,2,0) -> ADS10 | D15: =VLOOKUP($C15,'1.2 HR-Data luong'!$B:$BG,D$5,0) -> HR HN | E15: =VLOOKUP($C15,'1.2 HR-Data luong'!$B:$BG,E$5,0) -> NguyenVanK | F15: =VLOOKUP($C15,'1.2 HR-Data luong'!$B:$BG,F$5,0) -> Nguyễn Văn K | G15: =VLOOKUP($C15,'1.2 HR-Data luong'!$B:$BG,G$5,0) -> HN | H15: =VLOOKUP($C15,'1.2 HR-Data luong'!$B:$BG,H$5,0) -> Nhân viên | I15: =VLOOKUP($C15,'1.2 HR-Data luong'!$B:$BG,I$5,0) -> C1 | J15: =VLOOKUP($C15,'1.2 HR-Data luong'!$B:$BG,J$5,0) -> CT | K15: 300000 | L15: 10000000 | M15: 1000000 | N15: 0 | O15: 100000000 | P15: 0 | Q15: 50000000

Sheet 2.3 KT-GIAM TRU
A1: Các thông tin khác (trừ lương thưởng)
A3: Mã cty | B3: TT | C3: Mã NV | D3: Phòng | E3: HO TEN | F3: Họ tên | G3: VP | H3: Chức vụ | I3: Cấp bậc | J3: Loai HDLD | K3: Các khoản khác trừ lương | S3: Các khoản trừ thuế TNCN
K4: Bù MG | L4: Thẻ BHYT | M4: Thẻ xe | N4: Phạt KSNB | O4: Khác 1 […] | P4: Lý do phạt khác | Q4: Tổng phạt | R4: Tạm ứng (kế toán) | S4: Giảm trừ thu nhập chịu thuế | T4: Giảm trừ thuế TNCN | U4: Mức thuế TNCN cố định | V4: Số người phụ thuộc
C5: 1 | D5: 2 | E5: 3 | F5: 4 | G5: 5 | H5: 6 | I5: 7 | J5: 8 | K5: 9 | L5: 10 | M5: 11 | N5: 12 | O5: 13 | P5: 14 | Q5: 15 | R5: 16 | S5: 17 | T5: 18 | U5: 19 | V5: 20
A6: ADS | B6: 1 | C6: =VLOOKUP(B6,'1.2 HR-Data luong'!A:B,2,0) -> ADS01 | D6: =VLOOKUP($C6,'1.2 HR-Data luong'!$B:$BG,D$5,0) -> BD01 HN | E6: =VLOOKUP($C6,'1.2 HR-Data luong'!$B:$BG,E$5,0) -> NguyenVanA | F6: =VLOOKUP($C6,'1.2 HR-Data luong'!$B:$BG,F$5,0) -> Nguyễn Văn A | G6: =VLOOKUP($C6,'1.2 HR-Data luong'!$B:$BG,G$5,0) -> HN | H6: =VLOOKUP($C6,'1.2 HR-Data luong'!$B:$BG,H$5,0) -> Trưởng phòng | I6: =VLOOKUP($C6,'1.2 HR-Data luong'!$B:$BG,I$5,0) -> TP C1 | J6: =VLOOKUP($C6,'1.2 HR-Data luong'!$B:$BG,J$5,0) -> CT | S6: 10000000 | V6: 0
A7: ADS | B7: 2 | C7: =VLOOKUP(B7,'1.2 HR-Data luong'!A:B,2,0) -> ADS02 | D7: =VLOOKUP($C7,'1.2 HR-Data luong'!$B:$BG,D$5,0) -> BD01 HN | E7: =VLOOKUP($C7,'1.2 HR-Data luong'!$B:$BG,E$5,0) -> NguyenVanB | F7: =VLOOKUP($C7,'1.2 HR-Data luong'!$B:$BG,F$5,0) -> Nguyễn Văn B | G7: =VLOOKUP($C7,'1.2 HR-Data luong'!$B:$BG,G$5,0) -> HN | H7: =VLOOKUP($C7,'1.2 HR-Data luong'!$B:$BG,H$5,0) -> Nhân viên | I7: =VLOOKUP($C7,'1.2 HR-Data luong'!$B:$BG,I$5,0) -> C1 | J7: =VLOOKUP($C7,'1.2 HR-Data luong'!$B:$BG,J$5,0) -> CT | K7: 100000 | L7: 50000 | M7: 50000 | N7: 100000 | O7: 15000 | P7: Lý do phạt khác | Q7: =SUM(K7:O7) -> 315000 | R7: 500000 | V7: 0
A8: ADS | B8: 3 | C8: =VLOOKUP(B8,'1.2 HR-Data luong'!A:B,2,0) -> ADS03 | D8: =VLOOKUP($C8,'1.2 HR-Data luong'!$B:$BG,D$5,0) -> BD02 HN | E8: =VLOOKUP($C8,'1.2 HR-Data luong'!$B:$BG,E$5,0) -> NguyenVanC | F8: =VLOOKUP($C8,'1.2 HR-Data luong'!$B:$BG,F$5,0) -> Nguyễn Văn C | G8: =VLOOKUP($C8,'1.2 HR-Data luong'!$B:$BG,G$5,0) -> HN | H8: =VLOOKUP($C8,'1.2 HR-Data luong'!$B:$BG,H$5,0) -> Trưởng phòng | I8: =VLOOKUP($C8,'1.2 HR-Data luong'!$B:$BG,I$5,0) -> TP C2 | J8: =VLOOKUP($C8,'1.2 HR-Data luong'!$B:$BG,J$5,0) -> CT | T8: 1000000 | V8: 0
A9: ADS | B9: 4 | C9: =VLOOKUP(B9,'1.2 HR-Data luong'!A:B,2,0) -> ADS04 | D9: =VLOOKUP($C9,'1.2 HR-Data luong'!$B:$BG,D$5,0) -> BD02 HN | E9: =VLOOKUP($C9,'1.2 HR-Data luong'!$B:$BG,E$5,0) -> NguyenVanD | F9: =VLOOKUP($C9,'1.2 HR-Data luong'!$B:$BG,F$5,0) -> Nguyễn Văn D | G9: =VLOOKUP($C9,'1.2 HR-Data luong'!$B:$BG,G$5,0) -> HN | H9: =VLOOKUP($C9,'1.2 HR-Data luong'!$B:$BG,H$5,0) -> Nhân viên | I9: =VLOOKUP($C9,'1.2 HR-Data luong'!$B:$BG,I$5,0) -> C2 | J9: =VLOOKUP($C9,'1.2 HR-Data luong'!$B:$BG,J$5,0) -> CT | V9: 0
A10: ADS | B10: 5 | C10: =VLOOKUP(B10,'1.2 HR-Data luong'!A:B,2,0) -> ADS05 | D10: =VLOOKUP($C10,'1.2 HR-Data luong'!$B:$BG,D$5,0) -> BD02 HN | E10: =VLOOKUP($C10,'1.2 HR-Data luong'!$B:$BG,E$5,0) -> NguyenVanE | F10: =VLOOKUP($C10,'1.2 HR-Data luong'!$B:$BG,F$5,0) -> Nguyễn Văn E | G10: =VLOOKUP($C10,'1.2 HR-Data luong'!$B:$BG,G$5,0) -> HN | H10: =VLOOKUP($C10,'1.2 HR-Data luong'!$B:$BG,H$5,0) -> Nhân viên | I10: =VLOOKUP($C10,'1.2 HR-Data luong'!$B:$BG,I$5,0) -> C3 | J10: =VLOOKUP($C10,'1.2 HR-Data luong'!$B:$BG,J$5,0) -> CT | V10: 0
A11: ADS | B11: 6 | C11: =VLOOKUP(B11,'1.2 HR-Data luong'!A:B,2,0) -> ADS06 | D11: =VLOOKUP($C11,'1.2 HR-Data luong'!$B:$BG,D$5,0) -> BD03 SG | E11: =VLOOKUP($C11,'1.2 HR-Data luong'!$B:$BG,E$5,0) -> NguyenVanF | F11: =VLOOKUP($C11,'1.2 HR-Data luong'!$B:$BG,F$5,0) -> Nguyễn Văn F | G11: =VLOOKUP($C11,'1.2 HR-Data luong'!$B:$BG,G$5,0) -> HCM | H11: =VLOOKUP($C11,'1.2 HR-Data luong'!$B:$BG,H$5,0) -> Trưởng phòng | I11: =VLOOKUP($C11,'1.2 HR-Data luong'!$B:$BG,I$5,0) -> TP C3 | J11: =VLOOKUP($C11,'1.2 HR-Data luong'!$B:$BG,J$5,0) -> CT | V11: 0
A12: ADS | B12: 7 | C12: =VLOOKUP(B12,'1.2 HR-Data luong'!A:B,2,0) -> ADS07 | D12: =VLOOKUP($C12,'1.2 HR-Data luong'!$B:$BG,D$5,0) -> BD03 SG | E12: =VLOOKUP($C12,'1.2 HR-Data luong'!$B:$BG,E$5,0) -> NguyenVanG | F12: =VLOOKUP($C12,'1.2 HR-Data luong'!$B:$BG,F$5,0) -> Nguyễn Văn G | G12: =VLOOKUP($C12,'1.2 HR-Data luong'!$B:$BG,G$5,0) -> HCM | H12: =VLOOKUP($C12,'1.2 HR-Data luong'!$B:$BG,H$5,0) -> Nhân viên | I12: =VLOOKUP($C12,'1.2 HR-Data luong'!$B:$BG,I$5,0) -> C4 | J12: =VLOOKUP($C12,'1.2 HR-Data luong'!$B:$BG,J$5,0) -> CT | V12: 0
A13: ADS | B13: 8 | C13: =VLOOKUP(B13,'1.2 HR-Data luong'!A:B,2,0) -> ADS08 | D13: =VLOOKUP($C13,'1.2 HR-Data luong'!$B:$BG,D$5,0) -> BD03 SG | E13: =VLOOKUP($C13,'1.2 HR-Data luong'!$B:$BG,E$5,0) -> NguyenVanH | F13: =VLOOKUP($C13,'1.2 HR-Data luong'!$B:$BG,F$5,0) -> Nguyễn Văn H | G13: =VLOOKUP($C13,'1.2 HR-Data luong'!$B:$BG,G$5,0) -> HCM | H13: =VLOOKUP($C13,'1.2 HR-Data luong'!$B:$BG,H$5,0) -> Nhân viên | I13: =VLOOKUP($C13,'1.2 HR-Data luong'!$B:$BG,I$5,0) -> S1 | J13: =VLOOKUP($C13,'1.2 HR-Data luong'!$B:$BG,J$5,0) -> CT | U13: 2000000 | V13: 0
A14: ADS | B14: 9 | C14: =VLOOKUP(B14,'1.2 HR-Data luong'!A:B,2,0) -> ADS09 | D14: =VLOOKUP($C14,'1.2 HR-Data luong'!$B:$BG,D$5,0) -> HR HN | E14: =VLOOKUP($C14,'1.2 HR-Data luong'!$B:$BG,E$5,0) -> NguyenVanI | F14: =VLOOKUP($C14,'1.2 HR-Data luong'!$B:$BG,F$5,0) -> Nguyễn Văn I | G14: =VLOOKUP($C14,'1.2 HR-Data luong'!$B:$BG,G$5,0) -> HN | H14: =VLOOKUP($C14,'1.2 HR-Data luong'!$B:$BG,H$5,0) -> Trưởng phòng | I14: =VLOOKUP($C14,'1.2 HR-Data luong'!$B:$BG,I$5,0) -> TP KPC | J14: =VLOOKUP($C14,'1.2 HR-Data luong'!$B:$BG,J$5,0) -> CT | V14: 1
A15: ADS | B15: 10 | C15: =VLOOKUP(B15,'1.2 HR-Data luong'!A:B,2,0) -> ADS10 | D15: =VLOOKUP($C15,'1.2 HR-Data luong'!$B:$BG,D$5,0) -> HR HN | E15: =VLOOKUP($C15,'1.2 HR-Data luong'!$B:$BG,E$5,0) -> NguyenVanK | F15: =VLOOKUP($C15,'1.2 HR-Data luong'!$B:$BG,F$5,0) -> Nguyễn Văn K | G15: =VLOOKUP($C15,'1.2 HR-Data luong'!$B:$BG,G$5,0) -> HN | H15: =VLOOKUP($C15,'1.2 HR-Data luong'!$B:$BG,H$5,0) -> Nhân viên | I15: =VLOOKUP($C15,'1.2 HR-Data luong'!$B:$BG,I$5,0) -> C1 | J15: =VLOOKUP($C15,'1.2 HR-Data luong'!$B:$BG,J$5,0) -> CT | V15: 2

Sheet 3.1 ERP-MUC LUONG
A1: Bảng tính mức lương cứng
A3: Mã cty | B3: TT | C3: Mã NV | D3: Phòng | E3: HO TEN | F3: Họ tên | G3: VP | H3: Chức vụ | I3: Cấp bậc | J3: Loai HDLD | K3: MUC LUONG HUONG | O3: CHAM CONG | R3: Mức lương lên bảng lương
K4: LUONG THANG TRUOC | L4: LUONG DIEU CHINH | M4: NGAY DIEU CHINH | N4: NOI DUNG DIEU CHINH | O4: Trước điều chỉnh | P4: Sau điều chỉnh | Q4: Tổng
C5: 1 | D5: 2 | E5: 3 | F5: 4 | G5: 5 | H5: 6 | I5: 7 | J5: 8 | K5: 9 | L5: 10 | M5: 11 | N5: 12 | O5: 13 | P5: 14 | Q5: 15 | R5: 16
A6: ADS | B6: 1 | C6: =VLOOKUP(B6,'1.2 HR-Data luong'!A:B,2,0) -> ADS01 | D6: =VLOOKUP($C6,'1.2 HR-Data luong'!$B:$BG,D$5,0) -> BD01 HN | E6: =VLOOKUP($C6,'1.2 HR-Data luong'!$B:$BG,E$5,0) -> NguyenVanA | F6: =VLOOKUP($C6,'1.2 HR-Data luong'!$B:$BG,F$5,0) -> Nguyễn Văn A | G6: =VLOOKUP($C6,'1.2 HR-Data luong'!$B:$BG,G$5,0) -> HN | H6: =VLOOKUP($C6,'1.2 HR-Data luong'!$B:$BG,H$5,0) -> Trưởng phòng | I6: =VLOOKUP($C6,'1.2 HR-Data luong'!$B:$BG,I$5,0) -> TP C1 | J6: =VLOOKUP($C6,'1.2 HR-Data luong'!$B:$BG,J$5,0) -> CT | K6: =VLOOKUP($C6,'1.2 HR-Data luong'!$B:$BG,'1.2 HR-Data luong'!L$5,0) -> 1000000 | L6: =VLOOKUP($C6,'1.2 HR-Data luong'!$B:$BG,'1.2 HR-Data luong'!M$5,0) -> 5000000 | M6: =VLOOKUP($C6,'1.2 HR-Data luong'!$B:$BG,'1.2 HR-Data luong'!N$5,0) -> 42919 | N6: =VLOOKUP($C6,'1.2 HR-Data luong'!$B:$BG,'1.2 HR-Data luong'!O$5,0) -> Tăng lương do tăng cấp | O6: =VLOOKUP($C6,'1.2 HR-Data luong'!$B:$BG,'1.2 HR-Data luong'!P$5,0) -> 4 | P6: =VLOOKUP($C6,'1.2 HR-Data luong'!$B:$BG,'1.2 HR-Data luong'!Q$5,0) -> 18.5 | Q6: =VLOOKUP($C6,'1.2 HR-Data luong'!$B:$BG,'1.2 HR-Data luong'!R$5,0) -> 20.5 | R6: =(K6*O6+L6*P6)/Q6 -> 4707317.1
A7: ADS | B7: 2 | C7: =VLOOKUP(B7,'1.2 HR-Data luong'!A:B,2,0) -> ADS02 | D7: =VLOOKUP($C7,'1.2 HR-Data luong'!$B:$BG,D$5,0) -> BD01 HN | E7: =VLOOKUP($C7,'1.2 HR-Data luong'!$B:$BG,E$5,0) -> NguyenVanB | F7: =VLOOKUP($C7,'1.2 HR-Data luong'!$B:$BG,F$5,0) -> Nguyễn Văn B | G7: =VLOOKUP($C7,'1.2 HR-Data luong'!$B:$BG,G$5,0) -> HN | H7: =VLOOKUP($C7,'1.2 HR-Data luong'!$B:$BG,H$5,0) -> Nhân viên | I7: =VLOOKUP($C7,'1.2 HR-Data luong'!$B:$BG,I$5,0) -> C1 | J7: =VLOOKUP($C7,'1.2 HR-Data luong'!$B:$BG,J$5,0) -> CT | K7: =VLOOKUP($C7,'1.2 HR-Data luong'!$B:$BG,'1.2 HR-Data luong'!L$5,0) -> 2000000 | L7: =VLOOKUP($C7,'1.2 HR-Data luong'!$B:$BG,'1.2 HR-Data luong'!M$5,0) -> 0 | M7: =VLOOKUP($C7,'1.2 HR-Data luong'!$B:$BG,'1.2 HR-Data luong'!N$5,0) -> 0 | N7: =VLOOKUP($C7,'1.2 HR-Data luong'!$B:$BG,'1.2 HR-Data luong'!O$5,0) -> 0 | O7: =VLOOKUP($C7,'1.2 HR-Data luong'!$B:$BG,'1.2 HR-Data luong'!P$5,0) -> 22.5 | P7: =VLOOKUP($C7,'1.2 HR-Data luong'!$B:$BG,'1.2 HR-Data luong'!Q$5,0) -> 0 | Q7: =VLOOKUP($C7,'1.2 HR-Data luong'!$B:$BG,'1.2 HR-Data luong'!R$5,0) -> 20.5 | R7: =(K7*O7+L7*P7)/Q7 -> 2195122
A8: ADS | B8: 3 | C8: =VLOOKUP(B8,'1.2 HR-Data luong'!A:B,2,0) -> ADS03 | D8: =VLOOKUP($C8,'1.2 HR-Data luong'!$B:$BG,D$5,0) -> BD02 HN | E8: =VLOOKUP($C8,'1.2 HR-Data luong'!$B:$BG,E$5,0) -> NguyenVanC | F8: =VLOOKUP($C8,'1.2 HR-Data luong'!$B:$BG,F$5,0) -> Nguyễn Văn C | G8: =VLOOKUP($C8,'1.2 HR-Data luong'!$B:$BG,G$5,0) -> HN | H8: =VLOOKUP($C8,'1.2 HR-Data luong'!$B:$BG,H$5,0) -> Trưởng phòng | I8: =VLOOKUP($C8,'1.2 HR-Data luong'!$B:$BG,I$5,0) -> TP C2 | J8: =VLOOKUP($C8,'1.2 HR-Data luong'!$B:$BG,J$5,0) -> CT | K8: =VLOOKUP($C8,'1.2 HR-Data luong'!$B:$BG,'1.2 HR-Data luong'!L$5,0) -> 3000000 | L8: =VLOOKUP($C8,'1.2 HR-Data luong'!$B:$BG,'1.2 HR-Data luong'!M$5,0) -> 0 | M8: =VLOOKUP($C8,'1.2 HR-Data luong'!$B:$BG,'1.2 HR-Data luong'!N$5,0) -> 0 | N8: =VLOOKUP($C8,'1.2 HR-Data luong'!$B:$BG,'1.2 HR-Data luong'!O$5,0) -> 0 | O8: =VLOOKUP($C8,'1.2 HR-Data luong'!$B:$BG,'1.2 HR-Data luong'!P$5,0) -> 22.5 | P8: =VLOOKUP($C8,'1.2 HR-Data luong'!$B:$BG,'1.2 HR-Data luong'!Q$5,0) -> 0 | Q8: =VLOOKUP($C8,'1.2 HR-Data luong'!$B:$BG,'1.2 HR-Data luong'!R$5,0) -> 20.5 | R8: =(K8*O8+L8*P8)/Q8 -> 3292682.9
A9: ADS | B9: 4 | C9: =VLOOKUP(B9,'1.2 HR-Data luong'!A:B,2,0) -> ADS04 | D9: =VLOOKUP($C9,'1.2 HR-Data luong'!$B:$BG,D$5,0) -> BD02 HN | E9: =VLOOKUP($C9,'1.2 HR-Data luong'!$B:$BG,E$5,0) -> NguyenVanD | F9: =VLOOKUP($C9,'1.2 HR-Data luong'!$B:$BG,F$5,0) -> Nguyễn Văn D | G9: =VLOOKUP($C9,'1.2 HR-Data luong'!$B:$BG,G$5,0) -> HN | H9: =VLOOKUP($C9,'1.2 HR-Data luong'!$B:$BG,H$5,0) -> Nhân viên | I9: =VLOOKUP($C9,'1.2 HR-Data luong'!$B:$BG,I$5,0) -> C2 | J9: =VLOOKUP($C9,'1.2 HR-Data luong'!$B:$BG,J$5,0) -> CT | K9: =VLOOKUP($C9,'1.2 HR-Data luong'!$B:$BG,'1.2 HR-Data luong'!L$5,0) -> 4000000 | L9: =VLOOKUP($C9,'1.2 HR-Data luong'!$B:$BG,'1.2 HR-Data luong'!M$5,0) -> 0 | M9: =VLOOKUP($C9,'1.2 HR-Data luong'!$B:$BG,'1.2 HR-Data luong'!N$5,0) -> 0 | N9: =VLOOKUP($C9,'1.2 HR-Data luong'!$B:$BG,'1.2 HR-Data luong'!O$5,0) -> 0 | O9: =VLOOKUP($C9,'1.2 HR-Data luong'!$B:$BG,'1.2 HR-Data luong'!P$5,0) -> 22.5 | P9: =VLOOKUP($C9,'1.2 HR-Data luong'!$B:$BG,'1.2 HR-Data luong'!Q$5,0) -> 0 | Q9: =VLOOKUP($C9,'1.2 HR-Data luong'!$B:$BG,'1.2 HR-Data luong'!R$5,0) -> 20.5 | R9: =(K9*O9+L9*P9)/Q9 -> 4390243.9
A10: ADS | B10: 5 | C10: =VLOOKUP(B10,'1.2 HR-Data luong'!A:B,2,0) -> ADS05 | D10: =VLOOKUP($C10,'1.2 HR-Data luong'!$B:$BG,D$5,0) -> BD02 HN | E10: =VLOOKUP($C10,'1.2 HR-Data luong'!$B:$BG,E$5,0) -> NguyenVanE | F10: =VLOOKUP($C10,'1.2 HR-Data luong'!$B:$BG,F$5,0) -> Nguyễn Văn E | G10: =VLOOKUP($C10,'1.2 HR-Data luong'!$B:$BG,G$5,0) -> HN | H10: =VLOOKUP($C10,'1.2 HR-Data luong'!$B:$BG,H$5,0) -> Nhân viên | I10: =VLOOKUP($C10,'1.2 HR-Data luong'!$B:$BG,I$5,0) -> C3 | J10: =VLOOKUP($C10,'1.2 HR-Data luong'!$B:$BG,J$5,0) -> CT | K10: =VLOOKUP($C10,'1.2 HR-Data luong'!$B:$BG,'1.2 HR-Data luong'!L$5,0) -> 5000000 | L10: =VLOOKUP($C10,'1.2 HR-Data luong'!$B:$BG,'1.2 HR-Data luong'!M$5,0) -> 10000000 | M10: =VLOOKUP($C10,'1.2 HR-Data luong'!$B:$BG,'1.2 HR-Data luong'!N$5,0) -> 42917 | N10: =VLOOKUP($C10,'1.2 HR-Data luong'!$B:$BG,'1.2 HR-Data luong'!O$5,0) -> Tăng lương do tăng cấp | O10: =VLOOKUP($C10,'1.2 HR-Data luong'!$B:$BG,'1.2 HR-Data luong'!P$5,0) -> 2 | P10: =VLOOKUP($C10,'1.2 HR-Data luong'!$B:$BG,'1.2 HR-Data luong'!Q$5,0) -> 20.5 | Q10: =VLOOKUP($C10,'1.2 HR-Data luong'!$B:$BG,'1.2 HR-Data luong'!R$5,0) -> 20.5 | R10: =(K10*O10+L10*P10)/Q10 -> 10487805
A11: ADS | B11: 6 | C11: =VLOOKUP(B11,'1.2 HR-Data luong'!A:B,2,0) -> ADS06 | D11: =VLOOKUP($C11,'1.2 HR-Data luong'!$B:$BG,D$5,0) -> BD03 SG | E11: =VLOOKUP($C11,'1.2 HR-Data luong'!$B:$BG,E$5,0) -> NguyenVanF | F11: =VLOOKUP($C11,'1.2 HR-Data luong'!$B:$BG,F$5,0) -> Nguyễn Văn F | G11: =VLOOKUP($C11,'1.2 HR-Data luong'!$B:$BG,G$5,0) -> HCM | H11: =VLOOKUP($C11,'1.2 HR-Data luong'!$B:$BG,H$5,0) -> Trưởng phòng | I11: =VLOOKUP($C11,'1.2 HR-Data luong'!$B:$BG,I$5,0) -> TP C3 | J11: =VLOOKUP($C11,'1.2 HR-Data luong'!$B:$BG,J$5,0) -> CT | K11: =VLOOKUP($C11,'1.2 HR-Data luong'!$B:$BG,'1.2 HR-Data luong'!L$5,0) -> 6000000 | L11: =VLOOKUP($C11,'1.2 HR-Data luong'!$B:$BG,'1.2 HR-Data luong'!M$5,0) -> 0 | M11: =VLOOKUP($C11,'1.2 HR-Data luong'!$B:$BG,'1.2 HR-Data luong'!N$5,0) -> 0 | N11: =VLOOKUP($C11,'1.2 HR-Data luong'!$B:$BG,'1.2 HR-Data luong'!O$5,0) -> 0 | O11: =VLOOKUP($C11,'1.2 HR-Data luong'!$B:$BG,'1.2 HR-Data luong'!P$5,0) -> 22.5 | P11: =VLOOKUP($C11,'1.2 HR-Data luong'!$B:$BG,'1.2 HR-Data luong'!Q$5,0) -> 0 | Q11: =VLOOKUP($C11,'1.2 HR-Data luong'!$B:$BG,'1.2 HR-Data luong'!R$5,0) -> 22.5 | R11: =(K11*O11+L11*P11)/Q11 -> 6000000
A12: ADS | B12: 7 | C12: =VLOOKUP(B12,'1.2 HR-Data luong'!A:B,2,0) -> ADS07 | D12: =VLOOKUP($C12,'1.2 HR-Data luong'!$B:$BG,D$5,0) -> BD03 SG | E12: =VLOOKUP($C12,'1.2 HR-Data luong'!$B:$BG,E$5,0) -> NguyenVanG | F12: =VLOOKUP($C12,'1.2 HR-Data luong'!$B:$BG,F$5,0) -> Nguyễn Văn G | G12: =VLOOKUP($C12,'1.2 HR-Data luong'!$B:$BG,G$5,0) -> HCM | H12: =VLOOKUP($C12,'1.2 HR-Data luong'!$B:$BG,H$5,0) -> Nhân viên | I12: =VLOOKUP($C12,'1.2 HR-Data luong'!$B:$BG,I$5,0) -> C4 | J12: =VLOOKUP($C12,'1.2 HR-Data luong'!$B:$BG,J$5,0) -> CT | K12: =VLOOKUP($C12,'1.2 HR-Data luong'!$B:$BG,'1.2 HR-Data luong'!L$5,0) -> 7000000 | L12: =VLOOKUP($C12,'1.2 HR-Data luong'!$B:$BG,'1.2 HR-Data luong'!M$5,0) -> 0 | M12: =VLOOKUP($C12,'1.2 HR-Data luong'!$B:$BG,'1.2 HR-Data luong'!N$5,0) -> 0 | N12: =VLOOKUP($C12,'1.2 HR-Data luong'!$B:$BG,'1.2 HR-Data luong'!O$5,0) -> 0 | O12: =VLOOKUP($C12,'1.2 HR-Data luong'!$B:$BG,'1.2 HR-Data luong'!P$5,0) -> 22.5 | P12: =VLOOKUP($C12,'1.2 HR-Data luong'!$B:$BG,'1.2 HR-Data luong'!Q$5,0) -> 0 | Q12: =VLOOKUP($C12,'1.2 HR-Data luong'!$B:$BG,'1.2 HR-Data luong'!R$5,0) -> 22.5 | R12: =(K12*O12+L12*P12)/Q12 -> 7000000
A13: ADS | B13: 8 | C13: =VLOOKUP(B13,'1.2 HR-Data luong'!A:B,2,0) -> ADS08 | D13: =VLOOKUP($C13,'1.2 HR-Data luong'!$B:$BG,D$5,0) -> BD03 SG | E13: =VLOOKUP($C13,'1.2 HR-Data luong'!$B:$BG,E$5,0) -> NguyenVanH | F13: =VLOOKUP($C13,'1.2 HR-Data luong'!$B:$BG,F$5,0) -> Nguyễn Văn H | G13: =VLOOKUP($C13,'1.2 HR-Data luong'!$B:$BG,G$5,0) -> HCM | H13: =VLOOKUP($C13,'1.2 HR-Data luong'!$B:$BG,H$5,0) -> Nhân viên | I13: =VLOOKUP($C13,'1.2 HR-Data luong'!$B:$BG,I$5,0) -> S1 | J13: =VLOOKUP($C13,'1.2 HR-Data luong'!$B:$BG,J$5,0) -> CT | K13: =VLOOKUP($C13,'1.2 HR-Data luong'!$B:$BG,'1.2 HR-Data luong'!L$5,0) -> 8000000 | L13: =VLOOKUP($C13,'1.2 HR-Data luong'!$B:$BG,'1.2 HR-Data luong'!M$5,0) -> 10000000 | M13: =VLOOKUP($C13,'1.2 HR-Data luong'!$B:$BG,'1.2 HR-Data luong'!N$5,0) -> 42931 | N13: =VLOOKUP($C13,'1.2 HR-Data luong'!$B:$BG,'1.2 HR-Data luong'!O$5,0) -> Tăng lương do tăng cấp | O13: =VLOOKUP($C13,'1.2 HR-Data luong'!$B:$BG,'1.2 HR-Data luong'!P$5,0) -> 10 | P13: =VLOOKUP($C13,'1.2 HR-Data luong'!$B:$BG,'1.2 HR-Data luong'!Q$5,0) -> 12.5 | Q13: =VLOOKUP($C13,'1.2 HR-Data luong'!$B:$BG,'1.2 HR-Data luong'!R$5,0) -> 22.5 | R13: =(K13*O13+L13*P13)/Q13 -> 9111111.1
A14: ADS | B14: 9 | C14: =VLOOKUP(B14,'1.2 HR-Data luong'!A:B,2,0) -> ADS09 | D14: =VLOOKUP($C14,'1.2 HR-Data luong'!$B:$BG,D$5,0) -> HR HN | E14: =VLOOKUP($C14,'1.2 HR-Data luong'!$B:$BG,E$5,0) -> NguyenVanI | F14: =VLOOKUP($C14,'1.2 HR-Data luong'!$B:$BG,F$5,0) -> Nguyễn Văn I | G14: =VLOOKUP($C14,'1.2 HR-Data luong'!$B:$BG,G$5,0) -> HN | H14: =VLOOKUP($C14,'1.2 HR-Data luong'!$B:$BG,H$5,0) -> Trưởng phòng | I14: =VLOOKUP($C14,'1.2 HR-Data luong'!$B:$BG,I$5,0) -> TP KPC | J14: =VLOOKUP($C14,'1.2 HR-Data luong'!$B:$BG,J$5,0) -> CT | K14: =VLOOKUP($C14,'1.2 HR-Data luong'!$B:$BG,'1.2 HR-Data luong'!L$5,0) -> 9000000 | L14: =VLOOKUP($C14,'1.2 HR-Data luong'!$B:$BG,'1.2 HR-Data luong'!M$5,0) -> 0 | M14: =VLOOKUP($C14,'1.2 HR-Data luong'!$B:$BG,'1.2 HR-Data luong'!N$5,0) -> 0 | N14: =VLOOKUP($C14,'1.2 HR-Data luong'!$B:$BG,'1.2 HR-Data luong'!O$5,0) -> 0 | O14: =VLOOKUP($C14,'1.2 HR-Data luong'!$B:$BG,'1.2 HR-Data luong'!P$5,0) -> 22.5 | P14: =VLOOKUP($C14,'1.2 HR-Data luong'!$B:$BG,'1.2 HR-Data luong'!Q$5,0) -> 0 | Q14: =VLOOKUP($C14,'1.2 HR-Data luong'!$B:$BG,'1.2 HR-Data luong'!R$5,0) -> 22.5 | R14: =(K14*O14+L14*P14)/Q14 -> 9000000
A15: ADS | B15: 10 | C15: =VLOOKUP(B15,'1.2 HR-Data luong'!A:B,2,0) -> ADS10 | D15: =VLOOKUP($C15,'1.2 HR-Data luong'!$B:$BG,D$5,0) -> HR HN | E15: =VLOOKUP($C15,'1.2 HR-Data luong'!$B:$BG,E$5,0) -> NguyenVanK | F15: =VLOOKUP($C15,'1.2 HR-Data luong'!$B:$BG,F$5,0) -> Nguyễn Văn K | G15: =VLOOKUP($C15,'1.2 HR-Data luong'!$B:$BG,G$5,0) -> HN | H15: =VLOOKUP($C15,'1.2 HR-Data luong'!$B:$BG,H$5,0) -> Nhân viên | I15: =VLOOKUP($C15,'1.2 HR-Data luong'!$B:$BG,I$5,0) -> C1 | J15: =VLOOKUP($C15,'1.2 HR-Data luong'!$B:$BG,J$5,0) -> CT | K15: =VLOOKUP($C15,'1.2 HR-Data luong'!$B:$BG,'1.2 HR-Data luong'!L$5,0) -> 10000000 | L15: =VLOOKUP($C15,'1.2 HR-Data luong'!$B:$BG,'1.2 HR-Data luong'!M$5,0) -> 0 | M15: =VLOOKUP($C15,'1.2 HR-Data luong'!$B:$BG,'1.2 HR-Data luong'!N$5,0) -> 0 | N15: =VLOOKUP($C15,'1.2 HR-Data luong'!$B:$BG,'1.2 HR-Data luong'!O$5,0) -> 0 | O15: =VLOOKUP($C15,'1.2 HR-Data luong'!$B:$BG,'1.2 HR-Data luong'!P$5,0) -> 22.5 | P15: =VLOOKUP($C15,'1.2 HR-Data luong'!$B:$BG,'1.2 HR-Data luong'!Q$5,0) -> 0 | Q15: =VLOOKUP($C15,'1.2 HR-Data luong'!$B:$BG,'1.2 HR-Data luong'!R$5,0) -> 22.5 | R15: =(K15*O15+L15*P15)/Q15 -> 10000000

Sheet 3.2 ERP-PC THAM NIEN
A1: Bảng tính PC thâm niên
A3: Mã cty | B3: TT | C3: Mã NV | D3: Phòng | E3: HO TEN | F3: Họ tên | G3: VP | H3: Chức vụ | I3: Cấp bậc | J3: Loai HDLD | K3: MUC LUONG HUONG | O3: CHAM CONG | R3: Phụ cấp thâm niên | V3: Công tính % thâm niên | Y3: Mức lương 1 | Z3: Tỷ lệ thâm niên 1 | AA3: Số ngày (1) | AB3: Mức lương 1 | AC3: Tỷ lệ thâm niên 2 | AD3: Số ngày (2) | AE3: Mức lương 2 | AF3: Tỷ lệ thâm niên 1 | AG3: Số ngày (3) | AH3: Mức lương 2 | AI3: Tỷ lệ thâm niên 2 | AJ3: Số ngày (4) | AK3: Mức thâm niên
K4: LUONG THANG TRUOC | L4: LUONG DIEU CHINH | M4: NGAY DIEU CHINH | N4: NOI DUNG DIEU CHINH | O4: Trước điều chỉnh | P4: Sau điều chỉnh | Q4: Tổng | R4: % được hưởng tháng trước | S4: % điều chỉnh | T4: Ngày điều chỉnh | U4: Nội dung điều chỉnh | V4: Trước điều chỉnh | W4: Sau điều chỉnh | X4: Tổng | AL4: Check
C5: 1 | D5: 2 | E5: 3 | F5: 4 | G5: 5 | H5: 6 | I5: 7 | J5: 8 | K5: 9 | L5: 10 | M5: 11 | N5: 12 | O5: 13 | P5: 14 | Q5: 15 | R5: 16 | S5: 17 | T5: 18 | U5: 19 | V5: 20 | W5: 21 | X5: 22 | Y5: 23 | Z5: 24 | AA5: 25 | AB5: 26 | AC5: 27 | AD5: 28 | AE5: 29 | AF5: 30 | AG5: 31 | AH5: 32 | AI5: 33 | AJ5: 34 | AK5: 35
A6: ADS | B6: 1 | C6: =VLOOKUP(B6,'1.2 HR-Data luong'!A:B,2,0) -> ADS01 | D6: =VLOOKUP($C6,'1.2 HR-Data luong'!$B:$BG,D$5,0) -> BD01 HN | E6: =VLOOKUP($C6,'1.2 HR-Data luong'!$B:$BG,E$5,0) -> NguyenVanA | F6: =VLOOKUP($C6,'1.2 HR-Data luong'!$B:$BG,F$5,0) -> Nguyễn Văn A | G6: =VLOOKUP($C6,'1.2 HR-Data luong'!$B:$BG,G$5,0) -> HN | H6: =VLOOKUP($C6,'1.2 HR-Data luong'!$B:$BG,H$5,0) -> Trưởng phòng | I6: =VLOOKUP($C6,'1.2 HR-Data luong'!$B:$BG,I$5,0) -> TP C1 | J6: =VLOOKUP($C6,'1.2 HR-Data luong'!$B:$BG,J$5,0) -> CT | K6: =VLOOKUP($C6,'1.2 HR-Data luong'!$B:$BG,'1.2 HR-Data luong'!L$5,0) -> 1000000 | L6: =VLOOKUP($C6,'1.2 HR-Data luong'!$B:$BG,'1.2 HR-Data luong'!M$5,0) -> 5000000 | M6: =VLOOKUP($C6,'1.2 HR-Data luong'!$B:$BG,'1.2 HR-Data luong'!N$5,0) -> 42919 | N6: =VLOOKUP($C6,'1.2 HR-Data luong'!$B:$BG,'1.2 HR-Data luong'!O$5,0) -> Tăng lương do tăng cấp | O6: =VLOOKUP($C6,'1.2 HR-Data luong'!$B:$BG,'1.2 HR-Data luong'!P$5,0) -> 4 | P6: =VLOOKUP($C6,'1.2 HR-Data luong'!$B:$BG,'1.2 HR-Data luong'!Q$5,0) -> 18.5 | Q6: =VLOOKUP($C6,'1.2 HR-Data luong'!$B:$BG,'1.2 HR-Data luong'!R$5,0) -> 20.5 | R6: =VLOOKUP($C6,'1.2 HR-Data luong'!$B:$BG,'1.2 HR-Data luong'!W$5,0) -> 0.01 | S6: =VLOOKUP($C6,'1.2 HR-Data luong'!$B:$BG,'1.2 HR-Data luong'!X$5,0) -> 0.02 | T6: =VLOOKUP($C6,'1.2 HR-Data luong'!$B:$BG,'1.2 HR-Data luong'!Y$5,0) -> 42917 | U6: =VLOOKUP($C6,'1.2 HR-Data luong'!$B:$BG,'1.2 HR-Data luong'!Z$5,0) -> Đủ 3 năm công tác | V6: =VLOOKUP($C6,'1.2 HR-Data luong'!$B:$BG,'1.2 HR-Data luong'!AA$5,0) -> 2 | W6: =VLOOKUP($C6,'1.2 HR-Data luong'!$B:$BG,'1.2 HR-Data luong'!AB$5,0) -> 20.5 | X6: =VLOOKUP($C6,'1.2 HR-Data luong'!$B:$BG,'1.2 HR-Data luong'!AC$5,0) -> 22.5 | Y6: =K6 -> 1000000 | Z6: =R6 -> 0.01 | AA6: =MIN(O6,V6) -> 2 | AB6: =Y6 -> 1000000 | AC6: =IF(T6>0,S6,R6) -> 0.02 | AD6: =MAX(0,O6-AA6) -> 2 | AE6: =L6 -> 5000000 | AF6: =R6 -> 0.01 | AG6: =MAX(0,V6-AA6) -> 0 | AH6: =L6 -> 5000000 | AI6: =IF(T6>0,S6,R6) -> 0.02 | AJ6: =MAX(0,W6-AD6) -> 18.5 | AK6: =(Y6*Z6*AA6+AB6*AC6*AD6+AE6*AF6*AG6+AH6*AI6*AJ6)/(AA6+AD6+AG6+AJ6) -> 84888.889 | AL6: =SUM(AA6,AD6)-O6 -> 0 | AM6: =SUM(AG6,AJ6)-P6 -> 0 | AN6: =SUM(AA6,AG6)-V6 -> 0 | AO6: =SUM(AD6,AJ6)-W6 -> 0
A7: ADS | B7: 2 | C7: =VLOOKUP(B7,'1.2 HR-Data luong'!A:B,2,0) -> ADS02 | D7: =VLOOKUP($C7,'1.2 HR-Data luong'!$B:$BG,D$5,0) -> BD01 HN | E7: =VLOOKUP($C7,'1.2 HR-Data luong'!$B:$BG,E$5,0) -> NguyenVanB | F7: =VLOOKUP($C7,'1.2 HR-Data luong'!$B:$BG,F$5,0) -> Nguyễn Văn B | G7: =VLOOKUP($C7,'1.2 HR-Data luong'!$B:$BG,G$5,0) -> HN | H7: =VLOOKUP($C7,'1.2 HR-Data luong'!$B:$BG,H$5,0) -> Nhân viên | I7: =VLOOKUP($C7,'1.2 HR-Data luong'!$B:$BG,I$5,0) -> C1 | J7: =VLOOKUP($C7,'1.2 HR-Data luong'!$B:$BG,J$5,0) -> CT | K7: =VLOOKUP($C7,'1.2 HR-Data luong'!$B:$BG,'1.2 HR-Data luong'!L$5,0) -> 2000000 | L7: =VLOOKUP($C7,'1.2 HR-Data luong'!$B:$BG,'1.2 HR-Data luong'!M$5,0) -> 0 | M7: =VLOOKUP($C7,'1.2 HR-Data luong'!$B:$BG,'1.2 HR-Data luong'!N$5,0) -> 0 | N7: =VLOOKUP($C7,'1.2 HR-Data luong'!$B:$BG,'1.2 HR-Data luong'!O$5,0) -> 0 | O7: =VLOOKUP($C7,'1.2 HR-Data luong'!$B:$BG,'1.2 HR-Data luong'!P$5,0) -> 22.5 | P7: =VLOOKUP($C7,'1.2 HR-Data luong'!$B:$BG,'1.2 HR-Data luong'!Q$5,0) -> 0 | Q7: =VLOOKUP($C7,'1.2 HR-Data luong'!$B:$BG,'1.2 HR-Data luong'!R$5,0) -> 20.5 | R7: =VLOOKUP($C7,'1.2 HR-Data luong'!$B:$BG,'1.2 HR-Data luong'!W$5,0) -> 0.02 | S7: =VLOOKUP($C7,'1.2 HR-Data luong'!$B:$BG,'1.2 HR-Data luong'!X$5,0) -> 0 | T7: =VLOOKUP($C7,'1.2 HR-Data luong'!$B:$BG,'1.2 HR-Data luong'!Y$5,0) -> 0 | U7: =VLOOKUP($C7,'1.2 HR-Data luong'!$B:$BG,'1.2 HR-Data luong'!Z$5,0) -> 0 | V7: =VLOOKUP($C7,'1.2 HR-Data luong'!$B:$BG,'1.2 HR-Data luong'!AA$5,0) -> 22.5 | W7: =VLOOKUP($C7,'1.2 HR-Data luong'!$B:$BG,'1.2 HR-Data luong'!AB$5,0) -> 0 | X7: =VLOOKUP($C7,'1.2 HR-Data luong'!$B:$BG,'1.2 HR-Data luong'!AC$5,0) -> 22.5 | Y7: =K7 -> 2000000 | Z7: =R7 -> 0.02 | AA7: =MIN(O7,V7) -> 22.5 | AB7: =Y7 -> 2000000 | AC7: =IF(T7>0,S7,R7) -> 0.02 | AD7: =MAX(0,O7-AA7) -> 0 | AE7: =L7 -> 0 | AF7: =R7 -> 0.02 | AG7: =MAX(0,V7-AA7) -> 0 | AH7: =L7 -> 0 | AI7: =IF(T7>0,S7,R7) -> 0.02 | AJ7: =MAX(0,W7-AD7) -> 0 | AK7: =(Y7*Z7*AA7+AB7*AC7*AD7+AE7*AF7*AG7+AH7*AI7*AJ7)/(AA7+AD7+AG7+AJ7) -> 40000 | AL7: =SUM(AA7,AD7)-O7 -> 0 | AM7: =SUM(AG7,AJ7)-P7 -> 0 | AN7: =SUM(AA7,AG7)-V7 -> 0 | AO7: =SUM(AD7,AJ7)-W7 -> 0
A8: ADS | B8: 3 | C8: =VLOOKUP(B8,'1.2 HR-Data luong'!A:B,2,0) -> ADS03 | D8: =VLOOKUP($C8,'1.2 HR-Data luong'!$B:$BG,D$5,0) -> BD02 HN | E8: =VLOOKUP($C8,'1.2 HR-Data luong'!$B:$BG,E$5,0) -> NguyenVanC | F8: =VLOOKUP($C8,'1.2 HR-Data luong'!$B:$BG,F$5,0) -> Nguyễn Văn C | G8: =VLOOKUP($C8,'1.2 HR-Data luong'!$B:$BG,G$5,0) -> HN | H8: =VLOOKUP($C8,'1.2 HR-Data luong'!$B:$BG,H$5,0) -> Trưởng phòng | I8: =VLOOKUP($C8,'1.2 HR-Data luong'!$B:$BG,I$5,0) -> TP C2 | J8: =VLOOKUP($C8,'1.2 HR-Data luong'!$B:$BG,J$5,0) -> CT | K8: =VLOOKUP($C8,'1.2 HR-Data luong'!$B:$BG,'1.2 HR-Data luong'!L$5,0) -> 3000000 | L8: =VLOOKUP($C8,'1.2 HR-Data luong'!$B:$BG,'1.2 HR-Data luong'!M$5,0) -> 0 | M8: =VLOOKUP($C8,'1.2 HR-Data luong'!$B:$BG,'1.2 HR-Data luong'!N$5,0) -> 0 | N8: =VLOOKUP($C8,'1.2 HR-Data luong'!$B:$BG,'1.2 HR-Data luong'!O$5,0) -> 0 | O8: =VLOOKUP($C8,'1.2 HR-Data luong'!$B:$BG,'1.2 HR-Data luong'!P$5,0) -> 22.5 | P8: =VLOOKUP($C8,'1.2 HR-Data luong'!$B:$BG,'1.2 HR-Data luong'!Q$5,0) -> 0 | Q8: =VLOOKUP($C8,'1.2 HR-Data luong'!$B:$BG,'1.2 HR-Data luong'!R$5,0) -> 20.5 | R8: =VLOOKUP($C8,'1.2 HR-Data luong'!$B:$BG,'1.2 HR-Data luong'!W$5,0) -> 0.03 | S8: =VLOOKUP($C8,'1.2 HR-Data luong'!$B:$BG,'1.2 HR-Data luong'!X$5,0) -> 0 | T8: =VLOOKUP($C8,'1.2 HR-Data luong'!$B:$BG,'1.2 HR-Data luong'!Y$5,0) -> 0 | U8: =VLOOKUP($C8,'1.2 HR-Data luong'!$B:$BG,'1.2 HR-Data luong'!Z$5,0) -> 0 | V8: =VLOOKUP($C8,'1.2 HR-Data luong'!$B:$BG,'1.2 HR-Data luong'!AA$5,0) -> 22.5 | W8: =VLOOKUP($C8,'1.2 HR-Data luong'!$B:$BG,'1.2 HR-Data luong'!AB$5,0) -> 0 | X8: =VLOOKUP($C8,'1.2 HR-Data luong'!$B:$BG,'1.2 HR-Data luong'!AC$5,0) -> 22.5 | Y8: =K8 -> 3000000 | Z8: =R8 -> 0.03 | AA8: =MIN(O8,V8) -> 22.5 | AB8: =Y8 -> 3000000 | AC8: =IF(T8>0,S8,R8) -> 0.03 | AD8: =MAX(0,O8-AA8) -> 0 | AE8: =L8 -> 0 | AF8: =R8 -> 0.03 | AG8: =MAX(0,V8-AA8) -> 0 | AH8: =L8 -> 0 | AI8: =IF(T8>0,S8,R8) -> 0.03 | AJ8: =MAX(0,W8-AD8) -> 0 | AK8: =(Y8*Z8*AA8+AB8*AC8*AD8+AE8*AF8*AG8+AH8*AI8*AJ8)/(AA8+AD8+AG8+AJ8) -> 90000 | AL8: =SUM(AA8,AD8)-O8 -> 0 | AM8: =SUM(AG8,AJ8)-P8 -> 0 | AN8: =SUM(AA8,AG8)-V8 -> 0 | AO8: =SUM(AD8,AJ8)-W8 -> 0
A9: ADS | B9: 4 | C9: =VLOOKUP(B9,'1.2 HR-Data luong'!A:B,2,0) -> ADS04 | D9: =VLOOKUP($C9,'1.2 HR-Data luong'!$B:$BG,D$5,0) -> BD02 HN | E9: =VLOOKUP($C9,'1.2 HR-Data luong'!$B:$BG,E$5,0) -> NguyenVanD | F9: =VLOOKUP($C9,'1.2 HR-Data luong'!$B:$BG,F$5,0) -> Nguyễn Văn D | G9: =VLOOKUP($C9,'1.2 HR-Data luong'!$B:$BG,G$5,0) -> HN | H9: =VLOOKUP($C9,'1.2 HR-Data luong'!$B:$BG,H$5,0) -> Nhân viên | I9: =VLOOKUP($C9,'1.2 HR-Data luong'!$B:$BG,I$5,0) -> C2 | J9: =VLOOKUP($C9,'1.2 HR-Data luong'!$B:$BG,J$5,0) -> CT | K9: =VLOOKUP($C9,'1.2 HR-Data luong'!$B:$BG,'1.2 HR-Data luong'!L$5,0) -> 4000000 | L9: =VLOOKUP($C9,'1.2 HR-Data luong'!$B:$BG,'1.2 HR-Data luong'!M$5,0) -> 0 | M9: =VLOOKUP($C9,'1.2 HR-Data luong'!$B:$BG,'1.2 HR-Data luong'!N$5,0) -> 0 | N9: =VLOOKUP($C9,'1.2 HR-Data luong'!$B:$BG,'1.2 HR-Data luong'!O$5,0) -> 0 | O9: =VLOOKUP($C9,'1.2 HR-Data luong'!$B:$BG,'1.2 HR-Data luong'!P$5,0) -> 22.5 | P9: =VLOOKUP($C9,'1.2 HR-Data luong'!$B:$BG,'1.2 HR-Data luong'!Q$5,0) -> 0 | Q9: =VLOOKUP($C9,'1.2 HR-Data luong'!$B:$BG,'1.2 HR-Data luong'!R$5,0) -> 20.5 | R9: =VLOOKUP($C9,'1.2 HR-Data luong'!$B:$BG,'1.2 HR-Data luong'!W$5,0) -> 0.04 | S9: =VLOOKUP($C9,'1.2 HR-Data luong'!$B:$BG,'1.2 HR-Data luong'!X$5,0) -> 0 | T9: =VLOOKUP($C9,'1.2 HR-Data luong'!$B:$BG,'1.2 HR-Data luong'!Y$5,0) -> 0 | U9: =VLOOKUP($C9,'1.2 HR-Data luong'!$B:$BG,'1.2 HR-Data luong'!Z$5,0) -> 0 | V9: =VLOOKUP($C9,'1.2 HR-Data luong'!$B:$BG,'1.2 HR-Data luong'!AA$5,0) -> 22.5 | W9: =VLOOKUP($C9,'1.2 HR-Data luong'!$B:$BG,'1.2 HR-Data luong'!AB$5,0) -> 0 | X9: =VLOOKUP($C9,'1.2 HR-Data luong'!$B:$BG,'1.2 HR-Data luong'!AC$5,0) -> 22.5 | Y9: =K9 -> 4000000 | Z9: =R9 -> 0.04 | AA9: =MIN(O9,V9) -> 22.5 | AB9: =Y9 -> 4000000 | AC9: =IF(T9>0,S9,R9) -> 0.04 | AD9: =MAX(0,O9-AA9) -> 0 | AE9: =L9 -> 0 | AF9: =R9 -> 0.04 | AG9: =MAX(0,V9-AA9) -> 0 | AH9: =L9 -> 0 | AI9: =IF(T9>0,S9,R9) -> 0.04 | AJ9: =MAX(0,W9-AD9) -> 0 | AK9: =(Y9*Z9*AA9+AB9*AC9*AD9+AE9*AF9*AG9+AH9*AI9*AJ9)/(AA9+AD9+AG9+AJ9) -> 160000 | AL9: =SUM(AA9,AD9)-O9 -> 0 | AM9: =SUM(AG9,AJ9)-P9 -> 0 | AN9: =SUM(AA9,AG9)-V9 -> 0 | AO9: =SUM(AD9,AJ9)-W9 -> 0
A10: ADS | B10: 5 | C10: =VLOOKUP(B10,'1.2 HR-Data luong'!A:B,2,0) -> ADS05 | D10: =VLOOKUP($C10,'1.2 HR-Data luong'!$B:$BG,D$5,0) -> BD02 HN | E10: =VLOOKUP($C10,'1.2 HR-Data luong'!$B:$BG,E$5,0) -> NguyenVanE | F10: =VLOOKUP($C10,'1.2 HR-Data luong'!$B:$BG,F$5,0) -> Nguyễn Văn E | G10: =VLOOKUP($C10,'1.2 HR-Data luong'!$B:$BG,G$5,0) -> HN | H10: =VLOOKUP($C10,'1.2 HR-Data luong'!$B:$BG,H$5,0) -> Nhân viên | I10: =VLOOKUP($C10,'1.2 HR-Data luong'!$B:$BG,I$5,0) -> C3 | J10: =VLOOKUP($C10,'1.2 HR-Data luong'!$B:$BG,J$5,0) -> CT | K10: =VLOOKUP($C10,'1.2 HR-Data luong'!$B:$BG,'1.2 HR-Data luong'!L$5,0) -> 5000000 | L10: =VLOOKUP($C10,'1.2 HR-Data luong'!$B:$BG,'1.2 HR-Data luong'!M$5,0) -> 10000000 | M10: =VLOOKUP($C10,'1.2 HR-Data luong'!$B:$BG,'1.2 HR-Data luong'!N$5,0) -> 42917 | N10: =VLOOKUP($C10,'1.2 HR-Data luong'!$B:$BG,'1.2 HR-Data luong'!O$5,0) -> Tăng lương do tăng cấp | O10: =VLOOKUP($C10,'1.2 HR-Data luong'!$B:$BG,'1.2 HR-Data luong'!P$5,0) -> 2 | P10: =VLOOKUP($C10,'1.2 HR-Data luong'!$B:$BG,'1.2 HR-Data luong'!Q$5,0) -> 20.5 | Q10: =VLOOKUP($C10,'1.2 HR-Data luong'!$B:$BG,'1.2 HR-Data luong'!R$5,0) -> 20.5 | R10: =VLOOKUP($C10,'1.2 HR-Data luong'!$B:$BG,'1.2 HR-Data luong'!W$5,0) -> 0.05 | S10: =VLOOKUP($C10,'1.2 HR-Data luong'!$B:$BG,'1.2 HR-Data luong'!X$5,0) -> 0.06 | T10: =VLOOKUP($C10,'1.2 HR-Data luong'!$B:$BG,'1.2 HR-Data luong'!Y$5,0) -> 42916 | U10: =VLOOKUP($C10,'1.2 HR-Data luong'!$B:$BG,'1.2 HR-Data luong'!Z$5,0) -> Đủ 3 năm công tác | V10: =VLOOKUP($C10,'1.2 HR-Data luong'!$B:$BG,'1.2 HR-Data luong'!AA$5,0) -> 1 | W10: =VLOOKUP($C10,'1.2 HR-Data luong'!$B:$BG,'1.2 HR-Data luong'!AB$5,0) -> 21.5 | X10: =VLOOKUP($C10,'1.2 HR-Data luong'!$B:$BG,'1.2 HR-Data luong'!AC$5,0) -> 22.5 | Y10: =K10 -> 5000000 | Z10: =R10 -> 0.05 | AA10: =MIN(O10,V10) -> 1 | AB10: =Y10 -> 5000000 | AC10: =IF(T10>0,S10,R10) -> 0.06 | AD10: =MAX(0,O10-AA10) -> 1 | AE10: =L10 -> 10000000 | AF10: =R10 -> 0.05 | AG10: =MAX(0,V10-AA10) -> 0 | AH10: =L10 -> 10000000 | AI10: =IF(T10>0,S10,R10) -> 0.06 | AJ10: =MAX(0,W10-AD10) -> 20.5 | AK10: =(Y10*Z10*AA10+AB10*AC10*AD10+AE10*AF10*AG10+AH10*AI10*AJ10)/(AA10+AD10+AG10+AJ10) -> 571111.11 | AL10: =SUM(AA10,AD10)-O10 -> 0 | AM10: =SUM(AG10,AJ10)-P10 -> 0 | AN10: =SUM(AA10,AG10)-V10 -> 0 | AO10: =SUM(AD10,AJ10)-W10 -> 0
A11: ADS | B11: 6 | C11: =VLOOKUP(B11,'1.2 HR-Data luong'!A:B,2,0) -> ADS06 | D11: =VLOOKUP($C11,'1.2 HR-Data luong'!$B:$BG,D$5,0) -> BD03 SG | E11: =VLOOKUP($C11,'1.2 HR-Data luong'!$B:$BG,E$5,0) -> NguyenVanF | F11: =VLOOKUP($C11,'1.2 HR-Data luong'!$B:$BG,F$5,0) -> Nguyễn Văn F | G11: =VLOOKUP($C11,'1.2 HR-Data luong'!$B:$BG,G$5,0) -> HCM | H11: =VLOOKUP($C11,'1.2 HR-Data luong'!$B:$BG,H$5,0) -> Trưởng phòng | I11: =VLOOKUP($C11,'1.2 HR-Data luong'!$B:$BG,I$5,0) -> TP C3 | J11: =VLOOKUP($C11,'1.2 HR-Data luong'!$B:$BG,J$5,0) -> CT | K11: =VLOOKUP($C11,'1.2 HR-Data luong'!$B:$BG,'1.2 HR-Data luong'!L$5,0) -> 6000000 | L11: =VLOOKUP($C11,'1.2 HR-Data luong'!$B:$BG,'1.2 HR-Data luong'!M$5,0) -> 0 | M11: =VLOOKUP($C11,'1.2 HR-Data luong'!$B:$BG,'1.2 HR-Data luong'!N$5,0) -> 0 | N11: =VLOOKUP($C11,'1.2 HR-Data luong'!$B:$BG,'1.2 HR-Data luong'!O$5,0) -> 0 | O11: =VLOOKUP($C11,'1.2 HR-Data luong'!$B:$BG,'1.2 HR-Data luong'!P$5,0) -> 22.5 | P11: =VLOOKUP($C11,'1.2 HR-Data luong'!$B:$BG,'1.2 HR-Data luong'!Q$5,0) -> 0 | Q11: =VLOOKUP($C11,'1.2 HR-Data luong'!$B:$BG,'1.2 HR-Data luong'!R$5,0) -> 22.5 | R11: =VLOOKUP($C11,'1.2 HR-Data luong'!$B:$BG,'1.2 HR-Data luong'!W$5,0) -> 0.06 | S11: =VLOOKUP($C11,'1.2 HR-Data luong'!$B:$BG,'1.2 HR-Data luong'!X$5,0) -> 0 | T11: =VLOOKUP($C11,'1.2 HR-Data luong'!$B:$BG,'1.2 HR-Data luong'!Y$5,0) -> 0 | U11: =VLOOKUP($C11,'1.2 HR-Data luong'!$B:$BG,'1.2 HR-Data luong'!Z$5,0) -> 0 | V11: =VLOOKUP($C11,'1.2 HR-Data luong'!$B:$BG,'1.2 HR-Data luong'!AA$5,0) -> 22.5 | W11: =VLOOKUP($C11,'1.2 HR-Data luong'!$B:$BG,'1.2 HR-Data luong'!AB$5,0) -> 0 | X11: =VLOOKUP($C11,'1.2 HR-Data luong'!$B:$BG,'1.2 HR-Data luong'!AC$5,0) -> 22.5 | Y11: =K11 -> 6000000 | Z11: =R11 -> 0.06 | AA11: =MIN(O11,V11) -> 22.5 | AB11: =Y11 -> 6000000 | AC11: =IF(T11>0,S11,R11) -> 0.06 | AD11: =MAX(0,O11-AA11) -> 0 | AE11: =L11 -> 0 | AF11: =R11 -> 0.06 | AG11: =MAX(0,V11-AA11) -> 0 | AH11: =L11 -> 0 | AI11: =IF(T11>0,S11,R11) -> 0.06 | AJ11: =MAX(0,W11-AD11) -> 0 | AK11: =(Y11*Z11*AA11+AB11*AC11*AD11+AE11*AF11*AG11+AH11*AI11*AJ11)/(AA11+AD11+AG11+AJ11) -> 360000 | AL11: =SUM(AA11,AD11)-O11 -> 0 | AM11: =SUM(AG11,AJ11)-P11 -> 0 | AN11: =SUM(AA11,AG11)-V11 -> 0 | AO11: =SUM(AD11,AJ11)-W11 -> 0
